Workbook

Sheet Yoriqnoma
A1: 7A — monitoring jadvali (Informatika)
A3: Qanday ishlatish:
A4: 1. «Royxat» varag‘iga o‘quvchilar ism-familiyasini yozing (boshqa varaqlarga o‘zi o‘tadi).
A5: 2. «A_kirish» — oktabrdagi kirish testi: har bir savolga o‘quvchi belgilagan harfni (A/B/C/D) yozing.
A6: 3. «Amaliy» — amaliy topshiriq: har topshiriqqa 0, 1 yoki 2 ball (oktabr va yanvar ustunlari).
A7: 4. «B_yakuniy» — yanvardagi yakuniy test (B variant): xuddi shunday.
A8: 5. «Solishtirish» — avtomatik: o‘sish (Δ), normallashtirilgan o‘sish (g), daraja o‘zgarishi, sinf xulosasi va diagrammalar.
A9: 6. «Xarita» — kompyuter xonasidagi o‘tirish xaritasi (ism yodlash uchun).
A10: 7. «Darajalar» — chegaralar (85 / 65 / 45). O‘zgartirsangiz, hamma joyda qayta hisoblanadi.
A12: Muhim:
A13: • Saytda test o‘tkazgan bo‘lsangiz: admin → «CSV» → Q01…Q30 ustunlarini nusxalab, «A_kirish» ning C6 katagidan joylashtiring.
A14: • Qoidalar va talqin: 10_tahlil_va_darajalar.md.
... A16: • Yanvargacha zaxira nusxasini saqlang (fleshka / Google Drive).

Sheet Royxat
A1: № | B1: F.I.Sh. | C1: Laqab (qanday chaqirish) | D1: Guruh (1/2) | E1: Kompyuter № | F1: Qiziqishi | G1: Sinf rahbari izohi | H1: Ota-ona javobi | I1: Kuzatuv (1–3) | J1: Izoh
A2: 1
A3: 2
A4: 3
A5: 4
A6: 5
A7: 6
A8: 7
A9: 8
A10: 9
A11: 10
A12: 11
A13: 12
... A36: 35

Sheet A_kirish
A1: 7A — Kirish (diagnostik) testi — A variant
A2: Har bir o‘quvchi qatoriga u belgilagan harfni (A/B/C/D) yozing. Bo‘sh katak = javob bermagan. Sariq qatordagi kalitni o‘zgartirmang. Kulrang ustunlar avtomatik hisoblanadi.
C3: S1 | H3: S2 | M3: S3 | R3: S4 | W3: S5 | AB3: S6
A4: № | B4: F.I.Sh. | C4: 1 | D4: 2 | E4: 3 | F4: 4 | G4: 5 | H4: 6 | I4: 7 | J4: 8 | K4: 9 | L4: 10 | M4: 11 | N4: 12 | O4: 13 | P4: 14 | Q4: 15 | R4: 16 | S4: 17 | T4: 18 | U4: 19 | V4: 20 | W4: 21 | X4: 22 | Y4: 23 | Z4: 24 | AA4: 25 | AB4: 26 | AC4: 27 | AD4: 28 | AE4: 29 | AF4: 30 | AG4: S1 | AH4: S2 | AI4: S3 | AJ4: S4 | AK4: S5 | AL4: S6 | AM4: Tayanch % | AN4: 7-sinf % | AO4: Ball (30) | AP4: Jami % | AQ4: Daraja | AR4: 10 ball | AS4: 7-sinfga moslik | AT4: Guruh (taklif)
B5: KALIT → | C5: B | D5: D | E5: C | F5: B | G5: A | H5: D | I5: C | J5: C | K5: A | L5: B | M5: D | N5: A | O5: C | P5: A | Q5: C | R5: A | S5: B | T5: C | U5: A | V5: B | W5: C | X5: B | Y5: D | Z5: B | AA5: C | AB5: A | AC5: D | AD5: D | AE5: B | AF5: A
A6: 1 | B6: =IF(Royxat!B2="","",Royxat!B2) | AG6: =IF(COUNTA($C6:$AF6)=0,"",SUMPRODUCT(--(UPPER(TRIM(C6:G6))=C$5:G$5))) | AH6: =IF(COUNTA($C6:$AF6)=0,"",SUMPRODUCT(--(UPPER(TRIM(H6:L6))=H$5:L$5))) | AI6: =IF(COUNTA($C6:$AF6)=0,"",SUMPRODUCT(--(UPPER(TRIM(M6:Q6))=M$5:Q$5))) | AJ6: =IF(COUNTA($C6:$AF6)=0,"",SUMPRODUCT(--(UPPER(TRIM(R6:V6))=R$5:V$5))) | AK6: =IF(COUNTA($C6:$AF6)=0,"",SUMPRODUCT(--(UPPER(TRIM(W6:AA6))=W$5:AA$5))) | AL6: =IF(COUNTA($C6:$AF6)=0,"",SUMPRODUCT(--(UPPER(TRIM(AB6:AF6))=AB$5:AF$5))) | AM6: =IF(AG6="","",ROUND((AG6+AH6+AI6)/15*100,0)) | AN6: =IF(AG6="","",ROUND((AJ6+AK6+AL6)/15*100,0)) | AO6: =IF(AG6="","",SUM(AG6:AL6)) | AP6: =IF(AO6="","",ROUND(AO6/30*100,0)) | AQ6: =IF(AP6="","",IF(AP6>=Darajalar!$B$2,"Yuqori",IF(AP6>=Darajalar!$B$3,"Yaxshi",IF(AP6>=Darajalar!$B$4,"O‘rta","Boshlang‘ich")))) | AR6: =IF(AP6="","",ROUND(AP6/10,0)) | AS6: =IF(AM6="","",IF(AM6>=Darajalar!$B$3,"Mos",IF(AM6>=Darajalar!$B$4,"Qisman mos","Mos emas"))) | AT6: =IF(AP6="","",IF(AND(AP6>=75,OR(Amaliy!J6="",Amaliy!J6>=75)),"Ilg‘or",IF(OR(AP6<45,AND(Amaliy!J6<>"",Amaliy!J6<45)),"Yordam","Asosiy")))
A7: 2 | B7: =IF(Royxat!B3="","",Royxat!B3) | AG7: =IF(COUNTA($C7:$AF7)=0,"",SUMPRODUCT(--(UPPER(TRIM(C7:G7))=C$5:G$5))) | AH7: =IF(COUNTA($C7:$AF7)=0,"",SUMPRODUCT(--(UPPER(TRIM(H7:L7))=H$5:L$5))) | AI7: =IF(COUNTA($C7:$AF7)=0,"",SUMPRODUCT(--(UPPER(TRIM(M7:Q7))=M$5:Q$5))) | AJ7: =IF(COUNTA($C7:$AF7)=0,"",SUMPRODUCT(--(UPPER(TRIM(R7:V7))=R$5:V$5))) | AK7: =IF(COUNTA($C7:$AF7)=0,"",SUMPRODUCT(--(UPPER(TRIM(W7:AA7))=W$5:AA$5))) | AL7: =IF(COUNTA($C7:$AF7)=0,"",SUMPRODUCT(--(UPPER(TRIM(AB7:AF7))=AB$5:AF$5))) | AM7: =IF(AG7="","",ROUND((AG7+AH7+AI7)/15*100,0)) | AN7: =IF(AG7="","",ROUND((AJ7+AK7+AL7)/15*100,0)) | AO7: =IF(AG7="","",SUM(AG7:AL7)) | AP7: =IF(AO7="","",ROUND(AO7/30*100,0)) | AQ7: =IF(AP7="","",IF(AP7>=Darajalar!$B$2,"Yuqori",IF(AP7>=Darajalar!$B$3,"Yaxshi",IF(AP7>=Darajalar!$B$4,"O‘rta","Boshlang‘ich")))) | AR7: =IF(AP7="","",ROUND(AP7/10,0)) | AS7: =IF(AM7="","",IF(AM7>=Darajalar!$B$3,"Mos",IF(AM7>=Darajalar!$B$4,"Qisman mos","Mos emas"))) | AT7: =IF(AP7="","",IF(AND(AP7>=75,OR(Amaliy!J7="",Amaliy!J7>=75)),"Ilg‘or",IF(OR(AP7<45,AND(Amaliy!J7<>"",Amaliy!J7<45)),"Yordam","Asosiy")))
A8: 3 | B8: =IF(Royxat!B4="","",Royxat!B4) | AG8: =IF(COUNTA($C8:$AF8)=0,"",SUMPRODUCT(--(UPPER(TRIM(C8:G8))=C$5:G$5))) | AH8: =IF(COUNTA($C8:$AF8)=0,"",SUMPRODUCT(--(UPPER(TRIM(H8:L8))=H$5:L$5))) | AI8: =IF(COUNTA($C8:$AF8)=0,"",SUMPRODUCT(--(UPPER(TRIM(M8:Q8))=M$5:Q$5))) | AJ8: =IF(COUNTA($C8:$AF8)=0,"",SUMPRODUCT(--(UPPER(TRIM(R8:V8))=R$5:V$5))) | AK8: =IF(COUNTA($C8:$AF8)=0,"",SUMPRODUCT(--(UPPER(TRIM(W8:AA8))=W$5:AA$5))) | AL8: =IF(COUNTA($C8:$AF8)=0,"",SUMPRODUCT(--(UPPER(TRIM(AB8:AF8))=AB$5:AF$5))) | AM8: =IF(AG8="","",ROUND((AG8+AH8+AI8)/15*100,0)) | AN8: =IF(AG8="","",ROUND((AJ8+AK8+AL8)/15*100,0)) | AO8: =IF(AG8="","",SUM(AG8:AL8)) | AP8: =IF(AO8="","",ROUND(AO8/30*100,0)) | AQ8: =IF(AP8="","",IF(AP8>=Darajalar!$B$2,"Yuqori",IF(AP8>=Darajalar!$B$3,"Yaxshi",IF(AP8>=Darajalar!$B$4,"O‘rta","Boshlang‘ich")))) | AR8: =IF(AP8="","",ROUND(AP8/10,0)) | AS8: =IF(AM8="","",IF(AM8>=Darajalar!$B$3,"Mos",IF(AM8>=Darajalar!$B$4,"Qisman mos","Mos emas"))) | AT8: =IF(AP8="","",IF(AND(AP8>=75,OR(Amaliy!J8="",Amaliy!J8>=75)),"Ilg‘or",IF(OR(AP8<45,AND(Amaliy!J8<>"",Amaliy!J8<45)),"Yordam","Asosiy")))
A9: 4 | B9: =IF(Royxat!B5="","",Royxat!B5) | AG9: =IF(COUNTA($C9:$AF9)=0,"",SUMPRODUCT(--(UPPER(TRIM(C9:G9))=C$5:G$5))) | AH9: =IF(COUNTA($C9:$AF9)=0,"",SUMPRODUCT(--(UPPER(TRIM(H9:L9))=H$5:L$5))) | AI9: =IF(COUNTA($C9:$AF9)=0,"",SUMPRODUCT(--(UPPER(TRIM(M9:Q9))=M$5:Q$5))) | AJ9: =IF(COUNTA($C9:$AF9)=0,"",SUMPRODUCT(--(UPPER(TRIM(R9:V9))=R$5:V$5))) | AK9: =IF(COUNTA($C9:$AF9)=0,"",SUMPRODUCT(--(UPPER(TRIM(W9:AA9))=W$5:AA$5))) | AL9: =IF(COUNTA($C9:$AF9)=0,"",SUMPRODUCT(--(UPPER(TRIM(AB9:AF9))=AB$5:AF$5))) | AM9: =IF(AG9="","",ROUND((AG9+AH9+AI9)/15*100,0)) | AN9: =IF(AG9="","",ROUND((AJ9+AK9+AL9)/15*100,0)) | AO9: =IF(AG9="","",SUM(AG9:AL9)) | AP9: =IF(AO9="","",ROUND(AO9/30*100,0)) | AQ9: =IF(AP9="","",IF(AP9>=Darajalar!$B$2,"Yuqori",IF(AP9>=Darajalar!$B$3,"Yaxshi",IF(AP9>=Darajalar!$B$4,"O‘rta","Boshlang‘ich")))) | AR9: =IF(AP9="","",ROUND(AP9/10,0)) | AS9: =IF(AM9="","",IF(AM9>=Darajalar!$B$3,"Mos",IF(AM9>=Darajalar!$B$4,"Qisman mos","Mos emas"))) | AT9: =IF(AP9="","",IF(AND(AP9>=75,OR(Amaliy!J9="",Amaliy!J9>=75)),"Ilg‘or",IF(OR(AP9<45,AND(Amaliy!J9<>"",Amaliy!J9<45)),"Yordam","Asosiy")))
A10: 5 | B10: =IF(Royxat!B6="","",Royxat!B6) | AG10: =IF(COUNTA($C10:$AF10)=0,"",SUMPRODUCT(--(UPPER(TRIM(C10:G10))=C$5:G$5))) | AH10: =IF(COUNTA($C10:$AF10)=0,"",SUMPRODUCT(--(UPPER(TRIM(H10:L10))=H$5:L$5))) | AI10: =IF(COUNTA($C10:$AF10)=0,"",SUMPRODUCT(--(UPPER(TRIM(M10:Q10))=M$5:Q$5))) | AJ10: =IF(COUNTA($C10:$AF10)=0,"",SUMPRODUCT(--(UPPER(TRIM(R10:V10))=R$5:V$5))) | AK10: =IF(COUNTA($C10:$AF10)=0,"",SUMPRODUCT(--(UPPER(TRIM(W10:AA10))=W$5:AA$5))) | AL10: =IF(COUNTA($C10:$AF10)=0,"",SUMPRODUCT(--(UPPER(TRIM(AB10:AF10))=AB$5:AF$5))) | AM10: =IF(AG10="","",ROUND((AG10+AH10+AI10)/15*100,0)) | AN10: =IF(AG10="","",ROUND((AJ10+AK10+AL10)/15*100,0)) | AO10: =IF(AG10="","",SUM(AG10:AL10)) | AP10: =IF(AO10="","",ROUND(AO10/30*100,0)) | AQ10: =IF(AP10="","",IF(AP10>=Darajalar!$B$2,"Yuqori",IF(AP10>=Darajalar!$B$3,"Yaxshi",IF(AP10>=Darajalar!$B$4,"O‘rta","Boshlang‘ich")))) | AR10: =IF(AP10="","",ROUND(AP10/10,0)) | AS10: =IF(AM10="","",IF(AM10>=Darajalar!$B$3,"Mos",IF(AM10>=Darajalar!$B$4,"Qisman mos","Mos emas"))) | AT10: =IF(AP10="","",IF(AND(AP10>=75,OR(Amaliy!J10="",Amaliy!J10>=75)),"Ilg‘or",IF(OR(AP10<45,AND(Amaliy!J10<>"",Amaliy!J10<45)),"Yordam","Asosiy")))
A11: 6 | B11: =IF(Royxat!B7="","",Royxat!B7) | AG11: =IF(COUNTA($C11:$AF11)=0,"",SUMPRODUCT(--(UPPER(TRIM(C11:G11))=C$5:G$5))) | AH11: =IF(COUNTA($C11:$AF11)=0,"",SUMPRODUCT(--(UPPER(TRIM(H11:L11))=H$5:L$5))) | AI11: =IF(COUNTA($C11:$AF11)=0,"",SUMPRODUCT(--(UPPER(TRIM(M11:Q11))=M$5:Q$5))) | AJ11: =IF(COUNTA($C11:$AF11)=0,"",SUMPRODUCT(--(UPPER(TRIM(R11:V11))=R$5:V$5))) | AK11: =IF(COUNTA($C11:$AF11)=0,"",SUMPRODUCT(--(UPPER(TRIM(W11:AA11))=W$5:AA$5))) | AL11: =IF(COUNTA($C11:$AF11)=0,"",SUMPRODUCT(--(UPPER(TRIM(AB11:AF11))=AB$5:AF$5))) | AM11: =IF(AG11="","",ROUND((AG11+AH11+AI11)/15*100,0)) | AN11: =IF(AG11="","",ROUND((AJ11+AK11+AL11)/15*100,0)) | AO11: =IF(AG11="","",SUM(AG11:AL11)) | AP11: =IF(AO11="","",ROUND(AO11/30*100,0)) | AQ11: =IF(AP11="","",IF(AP11>=Darajalar!$B$2,"Yuqori",IF(AP11>=Darajalar!$B$3,"Yaxshi",IF(AP11>=Darajalar!$B$4,"O‘rta","Boshlang‘ich")))) | AR11: =IF(AP11="","",ROUND(AP11/10,0)) | AS11: =IF(AM11="","",IF(AM11>=Darajalar!$B$3,"Mos",IF(AM11>=Darajalar!$B$4,"Qisman mos","Mos emas"))) | AT11: =IF(AP11="","",IF(AND(AP11>=75,OR(Amaliy!J11="",Amaliy!J11>=75)),"Ilg‘or",IF(OR(AP11<45,AND(Amaliy!J11<>"",Amaliy!J11<45)),"Yordam","Asosiy")))
A12: 7 | B12: =IF(Royxat!B8="","",Royxat!B8) | AG12: =IF(COUNTA($C12:$AF12)=0,"",SUMPRODUCT(--(UPPER(TRIM(C12:G12))=C$5:G$5))) | AH12: =IF(COUNTA($C12:$AF12)=0,"",SUMPRODUCT(--(UPPER(TRIM(H12:L12))=H$5:L$5))) | AI12: =IF(COUNTA($C12:$AF12)=0,"",SUMPRODUCT(--(UPPER(TRIM(M12:Q12))=M$5:Q$5))) | AJ12: =IF(COUNTA($C12:$AF12)=0,"",SUMPRODUCT(--(UPPER(TRIM(R12:V12))=R$5:V$5))) | AK12: =IF(COUNTA($C12:$AF12)=0,"",SUMPRODUCT(--(UPPER(TRIM(W12:AA12))=W$5:AA$5))) | AL12: =IF(COUNTA($C12:$AF12)=0,"",SUMPRODUCT(--(UPPER(TRIM(AB12:AF12))=AB$5:AF$5))) | AM12: =IF(AG12="","",ROUND((AG12+AH12+AI12)/15*100,0)) | AN12: =IF(AG12="","",ROUND((AJ12+AK12+AL12)/15*100,0)) | AO12: =IF(AG12="","",SUM(AG12:AL12)) | AP12: =IF(AO12="","",ROUND(AO12/30*100,0)) | AQ12: =IF(AP12="","",IF(AP12>=Darajalar!$B$2,"Yuqori",IF(AP12>=Darajalar!$B$3,"Yaxshi",IF(AP12>=Darajalar!$B$4,"O‘rta","Boshlang‘ich")))) | AR12: =IF(AP12="","",ROUND(AP12/10,0)) | AS12: =IF(AM12="","",IF(AM12>=Darajalar!$B$3,"Mos",IF(AM12>=Darajalar!$B$4,"Qisman mos","Mos emas"))) | AT12: =IF(AP12="","",IF(AND(AP12>=75,OR(Amaliy!J12="",Amaliy!J12>=75)),"Ilg‘or",IF(OR(AP12<45,AND(Amaliy!J12<>"",Amaliy!J12<45)),"Yordam","Asosiy")))
A13: 8 | B13: =IF(Royxat!B9="","",Royxat!B9) | AG13: =IF(COUNTA($C13:$AF13)=0,"",SUMPRODUCT(--(UPPER(TRIM(C13:G13))=C$5:G$5))) | AH13: =IF(COUNTA($C13:$AF13)=0,"",SUMPRODUCT(--(UPPER(TRIM(H13:L13))=H$5:L$5))) | AI13: =IF(COUNTA($C13:$AF13)=0,"",SUMPRODUCT(--(UPPER(TRIM(M13:Q13))=M$5:Q$5))) | AJ13: =IF(COUNTA($C13:$AF13)=0,"",SUMPRODUCT(--(UPPER(TRIM(R13:V13))=R$5:V$5))) | AK13: =IF(COUNTA($C13:$AF13)=0,"",SUMPRODUCT(--(UPPER(TRIM(W13:AA13))=W$5:AA$5))) | AL13: =IF(COUNTA($C13:$AF13)=0,"",SUMPRODUCT(--(UPPER(TRIM(AB13:AF13))=AB$5:AF$5))) | AM13: =IF(AG13="","",ROUND((AG13+AH13+AI13)/15*100,0)) | AN13: =IF(AG13="","",ROUND((AJ13+AK13+AL13)/15*100,0)) | AO13: =IF(AG13="","",SUM(AG13:AL13)) | AP13: =IF(AO13="","",ROUND(AO13/30*100,0)) | AQ13: =IF(AP13="","",IF(AP13>=Darajalar!$B$2,"Yuqori",IF(AP13>=Darajalar!$B$3,"Yaxshi",IF(AP13>=Darajalar!$B$4,"O‘rta","Boshlang‘ich")))) | AR13: =IF(AP13="","",ROUND(AP13/10,0)) | AS13: =IF(AM13="","",IF(AM13>=Darajalar!$B$3,"Mos",IF(AM13>=Darajalar!$B$4,"Qisman mos","Mos emas"))) | AT13: =IF(AP13="","",IF(AND(AP13>=75,OR(Amaliy!J13="",Amaliy!J13>=75)),"Ilg‘or",IF(OR(AP13<45,AND(Amaliy!J13<>"",Amaliy!J13<45)),"Yordam","Asosiy")))
A14: 9 | B14: =IF(Royxat!B10="","",Royxat!B10) | AG14: =IF(COUNTA($C14:$AF14)=0,"",SUMPRODUCT(--(UPPER(TRIM(C14:G14))=C$5:G$5))) | AH14: =IF(COUNTA($C14:$AF14)=0,"",SUMPRODUCT(--(UPPER(TRIM(H14:L14))=H$5:L$5))) | AI14: =IF(COUNTA($C14:$AF14)=0,"",SUMPRODUCT(--(UPPER(TRIM(M14:Q14))=M$5:Q$5))) | AJ14: =IF(COUNTA($C14:$AF14)=0,"",SUMPRODUCT(--(UPPER(TRIM(R14:V14))=R$5:V$5))) | AK14: =IF(COUNTA($C14:$AF14)=0,"",SUMPRODUCT(--(UPPER(TRIM(W14:AA14))=W$5:AA$5))) | AL14: =IF(COUNTA($C14:$AF14)=0,"",SUMPRODUCT(--(UPPER(TRIM(AB14:AF14))=AB$5:AF$5))) | AM14: =IF(AG14="","",ROUND((AG14+AH14+AI14)/15*100,0)) | AN14: =IF(AG14="","",ROUND((AJ14+AK14+AL14)/15*100,0)) | AO14: =IF(AG14="","",SUM(AG14:AL14)) | AP14: =IF(AO14="","",ROUND(AO14/30*100,0)) | AQ14: =IF(AP14="","",IF(AP14>=Darajalar!$B$2,"Yuqori",IF(AP14>=Darajalar!$B$3,"Yaxshi",IF(AP14>=Darajalar!$B$4,"O‘rta","Boshlang‘ich")))) | AR14: =IF(AP14="","",ROUND(AP14/10,0)) | AS14: =IF(AM14="","",IF(AM14>=Darajalar!$B$3,"Mos",IF(AM14>=Darajalar!$B$4,"Qisman mos","Mos emas"))) | AT14: =IF(AP14="","",IF(AND(AP14>=75,OR(Amaliy!J14="",Amaliy!J14>=75)),"Ilg‘or",IF(OR(AP14<45,AND(Amaliy!J14<>"",Amaliy!J14<45)),"Yordam","Asosiy")))
A15: 10 | B15: =IF(Royxat!B11="","",Royxat!B11) | AG15: =IF(COUNTA($C15:$AF15)=0,"",SUMPRODUCT(--(UPPER(TRIM(C15:G15))=C$5:G$5))) | AH15: =IF(COUNTA($C15:$AF15)=0,"",SUMPRODUCT(--(UPPER(TRIM(H15:L15))=H$5:L$5))) | AI15: =IF(COUNTA($C15:$AF15)=0,"",SUMPRODUCT(--(UPPER(TRIM(M15:Q15))=M$5:Q$5))) | AJ15: =IF(COUNTA($C15:$AF15)=0,"",SUMPRODUCT(--(UPPER(TRIM(R15:V15))=R$5:V$5))) | AK15: =IF(COUNTA($C15:$AF15)=0,"",SUMPRODUCT(--(UPPER(TRIM(W15:AA15))=W$5:AA$5))) | AL15: =IF(COUNTA($C15:$AF15)=0,"",SUMPRODUCT(--(UPPER(TRIM(AB15:AF15))=AB$5:AF$5))) | AM15: =IF(AG15="","",ROUND((AG15+AH15+AI15)/15*100,0)) | AN15: =IF(AG15="","",ROUND((AJ15+AK15+AL15)/15*100,0)) | AO15: =IF(AG15="","",SUM(AG15:AL15)) | AP15: =IF(AO15="","",ROUND(AO15/30*100,0)) | AQ15: =IF(AP15="","",IF(AP15>=Darajalar!$B$2,"Yuqori",IF(AP15>=Darajalar!$B$3,"Yaxshi",IF(AP15>=Darajalar!$B$4,"O‘rta","Boshlang‘ich")))) | AR15: =IF(AP15="","",ROUND(AP15/10,0)) | AS15: =IF(AM15="","",IF(AM15>=Darajalar!$B$3,"Mos",IF(AM15>=Darajalar!$B$4,"Qisman mos","Mos emas"))) | AT15: =IF(AP15="","",IF(AND(AP15>=75,OR(Amaliy!J15="",Amaliy!J15>=75)),"Ilg‘or",IF(OR(AP15<45,AND(Amaliy!J15<>"",Amaliy!J15<45)),"Yordam","Asosiy")))
A16: 11 | B16: =IF(Royxat!B12="","",Royxat!B12) | AG16: =IF(COUNTA($C16:$AF16)=0,"",SUMPRODUCT(--(UPPER(TRIM(C16:G16))=C$5:G$5))) | AH16: =IF(COUNTA($C16:$AF16)=0,"",SUMPRODUCT(--(UPPER(TRIM(H16:L16))=H$5:L$5))) | AI16: =IF(COUNTA($C16:$AF16)=0,"",SUMPRODUCT(--(UPPER(TRIM(M16:Q16))=M$5:Q$5))) | AJ16: =IF(COUNTA($C16:$AF16)=0,"",SUMPRODUCT(--(UPPER(TRIM(R16:V16))=R$5:V$5))) | AK16: =IF(COUNTA($C16:$AF16)=0,"",SUMPRODUCT(--(UPPER(TRIM(W16:AA16))=W$5:AA$5))) | AL16: =IF(COUNTA($C16:$AF16)=0,"",SUMPRODUCT(--(UPPER(TRIM(AB16:AF16))=AB$5:AF$5))) | AM16: =IF(AG16="","",ROUND((AG16+AH16+AI16)/15*100,0)) | AN16: =IF(AG16="","",ROUND((AJ16+AK16+AL16)/15*100,0)) | AO16: =IF(AG16="","",SUM(AG16:AL16)) | AP16: =IF(AO16="","",ROUND(AO16/30*100,0)) | AQ16: =IF(AP16="","",IF(AP16>=Darajalar!$B$2,"Yuqori",IF(AP16>=Darajalar!$B$3,"Yaxshi",IF(AP16>=Darajalar!$B$4,"O‘rta","Boshlang‘ich")))) | AR16: =IF(AP16="","",ROUND(AP16/10,0)) | AS16: =IF(AM16="","",IF(AM16>=Darajalar!$B$3,"Mos",IF(AM16>=Darajalar!$B$4,"Qisman mos","Mos emas"))) | AT16: =IF(AP16="","",IF(AND(AP16>=75,OR(Amaliy!J16="",Amaliy!J16>=75)),"Ilg‘or",IF(OR(AP16<45,AND(Amaliy!J16<>"",Amaliy!J16<45)),"Yordam","Asosiy")))
A17: 12 | B17: =IF(Royxat!B13="","",Royxat!B13) | AG17: =IF(COUNTA($C17:$AF17)=0,"",SUMPRODUCT(--(UPPER(TRIM(C17:G17))=C$5:G$5))) | AH17: =IF(COUNTA($C17:$AF17)=0,"",SUMPRODUCT(--(UPPER(TRIM(H17:L17))=H$5:L$5))) | AI17: =IF(COUNTA($C17:$AF17)=0,"",SUMPRODUCT(--(UPPER(TRIM(M17:Q17))=M$5:Q$5))) | AJ17: =IF(COUNTA($C17:$AF17)=0,"",SUMPRODUCT(--(UPPER(TRIM(R17:V17))=R$5:V$5))) | AK17: =IF(COUNTA($C17:$AF17)=0,"",SUMPRODUCT(--(UPPER(TRIM(W17:AA17))=W$5:AA$5))) | AL17: =IF(COUNTA($C17:$AF17)=0,"",SUMPRODUCT(--(UPPER(TRIM(AB17:AF17))=AB$5:AF$5))) | AM17: =IF(AG17="","",ROUND((AG17+AH17+AI17)/15*100,0)) | AN17: =IF(AG17="","",ROUND((AJ17+AK17+AL17)/15*100,0)) | AO17: =IF(AG17="","",SUM(AG17:AL17)) | AP17: =IF(AO17="","",ROUND(AO17/30*100,0)) | AQ17: =IF(AP17="","",IF(AP17>=Darajalar!$B$2,"Yuqori",IF(AP17>=Darajalar!$B$3,"Yaxshi",IF(AP17>=Darajalar!$B$4,"O‘rta","Boshlang‘ich")))) | AR17: =IF(AP17="","",ROUND(AP17/10,0)) | AS17: =IF(AM17="","",IF(AM17>=Darajalar!$B$3,"Mos",IF(AM17>=Darajalar!$B$4,"Qisman mos","Mos emas"))) | AT17: =IF(AP17="","",IF(AND(AP17>=75,OR(Amaliy!J17="",Amaliy!J17>=75)),"Ilg‘or",IF(OR(AP17<45,AND(Amaliy!J17<>"",Amaliy!J17<45)),"Yordam","Asosiy")))
... A40: 35 | B40: =IF(Royxat!B36="","",Royxat!B36) | AG40: =IF(COUNTA($C40:$AF40)=0,"",SUMPRODUCT(--(UPPER(TRIM(C40:G40))=C$5:G$5))) | AH40: =IF(COUNTA($C40:$AF40)=0,"",SUMPRODUCT(--(UPPER(TRIM(H40:L40))=H$5:L$5))) | AI40: =IF(COUNTA($C40:$AF40)=0,"",SUMPRODUCT(--(UPPER(TRIM(M40:Q40))=M$5:Q$5))) | AJ40: =IF(COUNTA($C40:$AF40)=0,"",SUMPRODUCT(--(UPPER(TRIM(R40:V40))=R$5:V$5))) | AK40: =IF(COUNTA($C40:$AF40)=0,"",SUMPRODUCT(--(UPPER(TRIM(W40:AA40))=W$5:AA$5))) | AL40: =IF(COUNTA($C40:$AF40)=0,"",SUMPRODUCT(--(UPPER(TRIM(AB40:AF40))=AB$5:AF$5))) | AM40: =IF(AG40="","",ROUND((AG40+AH40+AI40)/15*100,0)) | AN40: =IF(AG40="","",ROUND((AJ40+AK40+AL40)/15*100,0)) | AO40: =IF(AG40="","",SUM(AG40:AL40)) | AP40: =IF(AO40="","",ROUND(AO40/30*100,0)) | AQ40: =IF(AP40="","",IF(AP40>=Darajalar!$B$2,"Yuqori",IF(AP40>=Darajalar!$B$3,"Yaxshi",IF(AP40>=Darajalar!$B$4,"O‘rta","Boshlang‘ich")))) | AR40: =IF(AP40="","",ROUND(AP40/10,0)) | AS40: =IF(AM40="","",IF(AM40>=Darajalar!$B$3,"Mos",IF(AM40>=Darajalar!$B$4,"Qisman mos","Mos emas"))) | AT40: =IF(AP40="","",IF(AND(AP40>=75,OR(Amaliy!J40="",Amaliy!J40>=75)),"Ilg‘or",IF(OR(AP40<45,AND(Amaliy!J40<>"",Amaliy!J40<45)),"Yordam","Asosiy")))
B42: Sinf o‘rtacha | AG42: =IFERROR(ROUND(AVERAGE(AG6:AG40),1),"") | AH42: =IFERROR(ROUND(AVERAGE(AH6:AH40),1),"") | AI42: =IFERROR(ROUND(AVERAGE(AI6:AI40),1),"") | AJ42: =IFERROR(ROUND(AVERAGE(AJ6:AJ40),1),"") | AK42: =IFERROR(ROUND(AVERAGE(AK6:AK40),1),"") | AL42: =IFERROR(ROUND(AVERAGE(AL6:AL40),1),"") | AM42: =IFERROR(ROUND(AVERAGE(AM6:AM40),1),"") | AN42: =IFERROR(ROUND(AVERAGE(AN6:AN40),1),"") | ... AP42: =IFERROR(ROUND(AVERAGE(AP6:AP40),1),"") | AR42: =IFERROR(ROUND(AVERAGE(AR6:AR40),1),"")
B43: Savol bo‘yicha to‘g‘ri % | C43: =IF(COUNT($AP$6:$AP$40)=0,"",ROUND(SUMPRODUCT(--(UPPER(TRIM(C$6:C$40))=C$5))/COUNT($AP$6:$AP$40)*100,0)) | D43: =IF(COUNT($AP$6:$AP$40)=0,"",ROUND(SUMPRODUCT(--(UPPER(TRIM(D$6:D$40))=D$5))/COUNT($AP$6:$AP$40)*100,0)) | E43: =IF(COUNT($AP$6:$AP$40)=0,"",ROUND(SUMPRODUCT(--(UPPER(TRIM(E$6:E$40))=E$5))/COUNT($AP$6:$AP$40)*100,0)) | F43: =IF(COUNT($AP$6:$AP$40)=0,"",ROUND(SUMPRODUCT(--(UPPER(TRIM(F$6:F$40))=F$5))/COUNT($AP$6:$AP$40)*100,0)) | G43: =IF(COUNT($AP$6:$AP$40)=0,"",ROUND(SUMPRODUCT(--(UPPER(TRIM(G$6:G$40))=G$5))/COUNT($AP$6:$AP$40)*100,0)) | H43: =IF(COUNT($AP$6:$AP$40)=0,"",ROUND(SUMPRODUCT(--(UPPER(TRIM(H$6:H$40))=H$5))/COUNT($AP$6:$AP$40)*100,0)) | I43: =IF(COUNT($AP$6:$AP$40)=0,"",ROUND(SUMPRODUCT(--(UPPER(TRIM(I$6:I$40))=I$5))/COUNT($AP$6:$AP$40)*100,0)) | J43: =IF(COUNT($AP$6:$AP$40)=0,"",ROUND(SUMPRODUCT(--(UPPER(TRIM(J$6:J$40))=J$5))/COUNT($AP$6:$AP$40)*100,0)) | ... AF43: =IF(COUNT($AP$6:$AP$40)=0,"",ROUND(SUMPRODUCT(--(UPPER(TRIM(AF$6:AF$40))=AF$5))/COUNT($AP$6:$AP$40)*100,0))
B44: 40 % dan past (qizil) savollar — butun sinf uchun qiyin mavzu.

Sheet Amaliy
A1: 7A — Amaliy topshiriq (07_amaliy_topshiriq.md). Har topshiriq: 0, 1 yoki 2 ball. Bajarilmagan topshiriqni bo‘sh qoldiring.
C3: 1-bosqich (oktabr) | K3: 2-bosqich (yanvar) | T3: Yozish tezligi (belgi/daq)
A4: № | B4: F.I.Sh. | C4: 1. Papka | D4: 2. Tezlik | E4: 3. Bezash | F4: 4. Saqlash | G4: 5. Scratch | H4: 6. Internet | I4: Ball | J4: % | K4: 1. Papka | L4: 2. Tezlik | M4: 3. Bezash | N4: 4. Saqlash | O4: 5. Scratch | P4: 6. Internet | Q4: Ball | R4: % | S4: O‘sish (%) | T4: Oktabr | U4: Yanvar | V4: O‘sish
A6: 1 | B6: =IF(Royxat!B2="","",Royxat!B2) | I6: =IF(COUNT(C6:H6)=0,"",SUM(C6:H6)) | J6: =IF(I6="","",ROUND(I6/(COUNT(C6:H6)*2)*100,0)) | Q6: =IF(COUNT(K6:P6)=0,"",SUM(K6:P6)) | R6: =IF(Q6="","",ROUND(Q6/(COUNT(K6:P6)*2)*100,0)) | S6: =IF(OR(J6="",R6=""),"",R6-J6) | V6: =IF(OR(T6="",U6=""),"",U6-T6)
A7: 2 | B7: =IF(Royxat!B3="","",Royxat!B3) | I7: =IF(COUNT(C7:H7)=0,"",SUM(C7:H7)) | J7: =IF(I7="","",ROUND(I7/(COUNT(C7:H7)*2)*100,0)) | Q7: =IF(COUNT(K7:P7)=0,"",SUM(K7:P7)) | R7: =IF(Q7="","",ROUND(Q7/(COUNT(K7:P7)*2)*100,0)) | S7: =IF(OR(J7="",R7=""),"",R7-J7) | V7: =IF(OR(T7="",U7=""),"",U7-T7)
A8: 3 | B8: =IF(Royxat!B4="","",Royxat!B4) | I8: =IF(COUNT(C8:H8)=0,"",SUM(C8:H8)) | J8: =IF(I8="","",ROUND(I8/(COUNT(C8:H8)*2)*100,0)) | Q8: =IF(COUNT(K8:P8)=0,"",SUM(K8:P8)) | R8: =IF(Q8="","",ROUND(Q8/(COUNT(K8:P8)*2)*100,0)) | S8: =IF(OR(J8="",R8=""),"",R8-J8) | V8: =IF(OR(T8="",U8=""),"",U8-T8)
A9: 4 | B9: =IF(Royxat!B5="","",Royxat!B5) | I9: =IF(COUNT(C9:H9)=0,"",SUM(C9:H9)) | J9: =IF(I9="","",ROUND(I9/(COUNT(C9:H9)*2)*100,0)) | Q9: =IF(COUNT(K9:P9)=0,"",SUM(K9:P9)) | R9: =IF(Q9="","",ROUND(Q9/(COUNT(K9:P9)*2)*100,0)) | S9: =IF(OR(J9="",R9=""),"",R9-J9) | V9: =IF(OR(T9="",U9=""),"",U9-T9)
A10: 5 | B10: =IF(Royxat!B6="","",Royxat!B6) | I10: =IF(COUNT(C10:H10)=0,"",SUM(C10:H10)) | J10: =IF(I10="","",ROUND(I10/(COUNT(C10:H10)*2)*100,0)) | Q10: =IF(COUNT(K10:P10)=0,"",SUM(K10:P10)) | R10: =IF(Q10="","",ROUND(Q10/(COUNT(K10:P10)*2)*100,0)) | S10: =IF(OR(J10="",R10=""),"",R10-J10) | V10: =IF(OR(T10="",U10=""),"",U10-T10)
A11: 6 | B11: =IF(Royxat!B7="","",Royxat!B7) | I11: =IF(COUNT(C11:H11)=0,"",SUM(C11:H11)) | J11: =IF(I11="","",ROUND(I11/(COUNT(C11:H11)*2)*100,0)) | Q11: =IF(COUNT(K11:P11)=0,"",SUM(K11:P11)) | R11: =IF(Q11="","",ROUND(Q11/(COUNT(K11:P11)*2)*100,0)) | S11: =IF(OR(J11="",R11=""),"",R11-J11) | V11: =IF(OR(T11="",U11=""),"",U11-T11)
A12: 7 | B12: =IF(Royxat!B8="","",Royxat!B8) | I12: =IF(COUNT(C12:H12)=0,"",SUM(C12:H12)) | J12: =IF(I12="","",ROUND(I12/(COUNT(C12:H12)*2)*100,0)) | Q12: =IF(COUNT(K12:P12)=0,"",SUM(K12:P12)) | R12: =IF(Q12="","",ROUND(Q12/(COUNT(K12:P12)*2)*100,0)) | S12: =IF(OR(J12="",R12=""),"",R12-J12) | V12: =IF(OR(T12="",U12=""),"",U12-T12)
A13: 8 | B13: =IF(Royxat!B9="","",Royxat!B9) | I13: =IF(COUNT(C13:H13)=0,"",SUM(C13:H13)) | J13: =IF(I13="","",ROUND(I13/(COUNT(C13:H13)*2)*100,0)) | Q13: =IF(COUNT(K13:P13)=0,"",SUM(K13:P13)) | R13: =IF(Q13="","",ROUND(Q13/(COUNT(K13:P13)*2)*100,0)) | S13: =IF(OR(J13="",R13=""),"",R13-J13) | V13: =IF(OR(T13="",U13=""),"",U13-T13)
A14: 9 | B14: =IF(Royxat!B10="","",Royxat!B10) | I14: =IF(COUNT(C14:H14)=0,"",SUM(C14:H14)) | J14: =IF(I14="","",ROUND(I14/(COUNT(C14:H14)*2)*100,0)) | Q14: =IF(COUNT(K14:P14)=0,"",SUM(K14:P14)) | R14: =IF(Q14="","",ROUND(Q14/(COUNT(K14:P14)*2)*100,0)) | S14: =IF(OR(J14="",R14=""),"",R14-J14) | V14: =IF(OR(T14="",U14=""),"",U14-T14)
A15: 10 | B15: =IF(Royxat!B11="","",Royxat!B11) | I15: =IF(COUNT(C15:H15)=0,"",SUM(C15:H15)) | J15: =IF(I15="","",ROUND(I15/(COUNT(C15:H15)*2)*100,0)) | Q15: =IF(COUNT(K15:P15)=0,"",SUM(K15:P15)) | R15: =IF(Q15="","",ROUND(Q15/(COUNT(K15:P15)*2)*100,0)) | S15: =IF(OR(J15="",R15=""),"",R15-J15) | V15: =IF(OR(T15="",U15=""),"",U15-T15)
A16: 11 | B16: =IF(Royxat!B12="","",Royxat!B12) | I16: =IF(COUNT(C16:H16)=0,"",SUM(C16:H16)) | J16: =IF(I16="","",ROUND(I16/(COUNT(C16:H16)*2)*100,0)) | Q16: =IF(COUNT(K16:P16)=0,"",SUM(K16:P16)) | R16: =IF(Q16="","",ROUND(Q16/(COUNT(K16:P16)*2)*100,0)) | S16: =IF(OR(J16="",R16=""),"",R16-J16) | V16: =IF(OR(T16="",U16=""),"",U16-T16)
A17: 12 | B17: =IF(Royxat!B13="","",Royxat!B13) | I17: =IF(COUNT(C17:H17)=0,"",SUM(C17:H17)) | J17: =IF(I17="","",ROUND(I17/(COUNT(C17:H17)*2)*100,0)) | Q17: =IF(COUNT(K17:P17)=0,"",SUM(K17:P17)) | R17: =IF(Q17="","",ROUND(Q17/(COUNT(K17:P17)*2)*100,0)) | S17: =IF(OR(J17="",R17=""),"",R17-J17) | V17: =IF(OR(T17="",U17=""),"",U17-T17)
... A40: 35 | B40: =IF(Royxat!B36="","",Royxat!B36) | I40: =IF(COUNT(C40:H40)=0,"",SUM(C40:H40)) | J40: =IF(I40="","",ROUND(I40/(COUNT(C40:H40)*2)*100,0)) | Q40: =IF(COUNT(K40:P40)=0,"",SUM(K40:P40)) | R40: =IF(Q40="","",ROUND(Q40/(COUNT(K40:P40)*2)*100,0)) | S40: =IF(OR(J40="",R40=""),"",R40-J40) | V40: =IF(OR(T40="",U40=""),"",U40-T40)

Sheet B_yakuniy
A1: 7A — Yakuniy (takroriy) test — B variant
A2: Har bir o‘quvchi qatoriga u belgilagan harfni (A/B/C/D) yozing. Bo‘sh katak = javob bermagan. Sariq qatordagi kalitni o‘zgartirmang. Kulrang ustunlar avtomatik hisoblanadi.
C3: S1 | H3: S2 | M3: S3 | R3: S4 | W3: S5 | AB3: S6
A4: № | B4: F.I.Sh. | C4: 1 | D4: 2 | E4: 3 | F4: 4 | G4: 5 | H4: 6 | I4: 7 | J4: 8 | K4: 9 | L4: 10 | M4: 11 | N4: 12 | O4: 13 | P4: 14 | Q4: 15 | R4: 16 | S4: 17 | T4: 18 | U4: 19 | V4: 20 | W4: 21 | X4: 22 | Y4: 23 | Z4: 24 | AA4: 25 | AB4: 26 | AC4: 27 | AD4: 28 | AE4: 29 | AF4: 30 | AG4: S1 | AH4: S2 | AI4: S3 | AJ4: S4 | AK4: S5 | AL4: S6 | AM4: Tayanch % | AN4: 7-sinf % | AO4: Ball (30) | AP4: Jami % | AQ4: Daraja | AR4: 10 ball | AS4: 7-sinfga moslik | AT4: Guruh (taklif)
B5: KALIT → | C5: D | D5: B | E5: A | F5: D | G5: C | H5: B | I5: A | J5: B | K5: C | L5: D | M5: B | N5: D | O5: B | P5: C | Q5: B | R5: D | S5: A | T5: D | U5: C | V5: C | W5: A | X5: C | Y5: A | Z5: D | AA5: B | AB5: D | AC5: B | AD5: A | AE5: C | AF5: C
A6: 1 | B6: =IF(Royxat!B2="","",Royxat!B2) | AG6: =IF(COUNTA($C6:$AF6)=0,"",SUMPRODUCT(--(UPPER(TRIM(C6:G6))=C$5:G$5))) | AH6: =IF(COUNTA($C6:$AF6)=0,"",SUMPRODUCT(--(UPPER(TRIM(H6:L6))=H$5:L$5))) | AI6: =IF(COUNTA($C6:$AF6)=0,"",SUMPRODUCT(--(UPPER(TRIM(M6:Q6))=M$5:Q$5))) | AJ6: =IF(COUNTA($C6:$AF6)=0,"",SUMPRODUCT(--(UPPER(TRIM(R6:V6))=R$5:V$5))) | AK6: =IF(COUNTA($C6:$AF6)=0,"",SUMPRODUCT(--(UPPER(TRIM(W6:AA6))=W$5:AA$5))) | AL6: =IF(COUNTA($C6:$AF6)=0,"",SUMPRODUCT(--(UPPER(TRIM(AB6:AF6))=AB$5:AF$5))) | AM6: =IF(AG6="","",ROUND((AG6+AH6+AI6)/15*100,0)) | AN6: =IF(AG6="","",ROUND((AJ6+AK6+AL6)/15*100,0)) | AO6: =IF(AG6="","",SUM(AG6:AL6)) | AP6: =IF(AO6="","",ROUND(AO6/30*100,0)) | AQ6: =IF(AP6="","",IF(AP6>=Darajalar!$B$2,"Yuqori",IF(AP6>=Darajalar!$B$3,"Yaxshi",IF(AP6>=Darajalar!$B$4,"O‘rta","Boshlang‘ich")))) | AR6: =IF(AP6="","",ROUND(AP6/10,0)) | AS6: =IF(AM6="","",IF(AM6>=Darajalar!$B$3,"Mos",IF(AM6>=Darajalar!$B$4,"Qisman mos","Mos emas"))) | AT6: =IF(AP6="","",IF(AND(AP6>=75,OR(Amaliy!R6="",Amaliy!R6>=75)),"Ilg‘or",IF(OR(AP6<45,AND(Amaliy!R6<>"",Amaliy!R6<45)),"Yordam","Asosiy")))
A7: 2 | B7: =IF(Royxat!B3="","",Royxat!B3) | AG7: =IF(COUNTA($C7:$AF7)=0,"",SUMPRODUCT(--(UPPER(TRIM(C7:G7))=C$5:G$5))) | AH7: =IF(COUNTA($C7:$AF7)=0,"",SUMPRODUCT(--(UPPER(TRIM(H7:L7))=H$5:L$5))) | AI7: =IF(COUNTA($C7:$AF7)=0,"",SUMPRODUCT(--(UPPER(TRIM(M7:Q7))=M$5:Q$5))) | AJ7: =IF(COUNTA($C7:$AF7)=0,"",SUMPRODUCT(--(UPPER(TRIM(R7:V7))=R$5:V$5))) | AK7: =IF(COUNTA($C7:$AF7)=0,"",SUMPRODUCT(--(UPPER(TRIM(W7:AA7))=W$5:AA$5))) | AL7: =IF(COUNTA($C7:$AF7)=0,"",SUMPRODUCT(--(UPPER(TRIM(AB7:AF7))=AB$5:AF$5))) | AM7: =IF(AG7="","",ROUND((AG7+AH7+AI7)/15*100,0)) | AN7: =IF(AG7="","",ROUND((AJ7+AK7+AL7)/15*100,0)) | AO7: =IF(AG7="","",SUM(AG7:AL7)) | AP7: =IF(AO7="","",ROUND(AO7/30*100,0)) | AQ7: =IF(AP7="","",IF(AP7>=Darajalar!$B$2,"Yuqori",IF(AP7>=Darajalar!$B$3,"Yaxshi",IF(AP7>=Darajalar!$B$4,"O‘rta","Boshlang‘ich")))) | AR7: =IF(AP7="","",ROUND(AP7/10,0)) | AS7: =IF(AM7="","",IF(AM7>=Darajalar!$B$3,"Mos",IF(AM7>=Darajalar!$B$4,"Qisman mos","Mos emas"))) | AT7: =IF(AP7="","",IF(AND(AP7>=75,OR(Amaliy!R7="",Amaliy!R7>=75)),"Ilg‘or",IF(OR(AP7<45,AND(Amaliy!R7<>"",Amaliy!R7<45)),"Yordam","Asosiy")))
A8: 3 | B8: =IF(Royxat!B4="","",Royxat!B4) | AG8: =IF(COUNTA($C8:$AF8)=0,"",SUMPRODUCT(--(UPPER(TRIM(C8:G8))=C$5:G$5))) | AH8: =IF(COUNTA($C8:$AF8)=0,"",SUMPRODUCT(--(UPPER(TRIM(H8:L8))=H$5:L$5))) | AI8: =IF(COUNTA($C8:$AF8)=0,"",SUMPRODUCT(--(UPPER(TRIM(M8:Q8))=M$5:Q$5))) | AJ8: =IF(COUNTA($C8:$AF8)=0,"",SUMPRODUCT(--(UPPER(TRIM(R8:V8))=R$5:V$5))) | AK8: =IF(COUNTA($C8:$AF8)=0,"",SUMPRODUCT(--(UPPER(TRIM(W8:AA8))=W$5:AA$5))) | AL8: =IF(COUNTA($C8:$AF8)=0,"",SUMPRODUCT(--(UPPER(TRIM(AB8:AF8))=AB$5:AF$5))) | AM8: =IF(AG8="","",ROUND((AG8+AH8+AI8)/15*100,0)) | AN8: =IF(AG8="","",ROUND((AJ8+AK8+AL8)/15*100,0)) | AO8: =IF(AG8="","",SUM(AG8:AL8)) | AP8: =IF(AO8="","",ROUND(AO8/30*100,0)) | AQ8: =IF(AP8="","",IF(AP8>=Darajalar!$B$2,"Yuqori",IF(AP8>=Darajalar!$B$3,"Yaxshi",IF(AP8>=Darajalar!$B$4,"O‘rta","Boshlang‘ich")))) | AR8: =IF(AP8="","",ROUND(AP8/10,0)) | AS8: =IF(AM8="","",IF(AM8>=Darajalar!$B$3,"Mos",IF(AM8>=Darajalar!$B$4,"Qisman mos","Mos emas"))) | AT8: =IF(AP8="","",IF(AND(AP8>=75,OR(Amaliy!R8="",Amaliy!R8>=75)),"Ilg‘or",IF(OR(AP8<45,AND(Amaliy!R8<>"",Amaliy!R8<45)),"Yordam","Asosiy")))
A9: 4 | B9: =IF(Royxat!B5="","",Royxat!B5) | AG9: =IF(COUNTA($C9:$AF9)=0,"",SUMPRODUCT(--(UPPER(TRIM(C9:G9))=C$5:G$5))) | AH9: =IF(COUNTA($C9:$AF9)=0,"",SUMPRODUCT(--(UPPER(TRIM(H9:L9))=H$5:L$5))) | AI9: =IF(COUNTA($C9:$AF9)=0,"",SUMPRODUCT(--(UPPER(TRIM(M9:Q9))=M$5:Q$5))) | AJ9: =IF(COUNTA($C9:$AF9)=0,"",SUMPRODUCT(--(UPPER(TRIM(R9:V9))=R$5:V$5))) | AK9: =IF(COUNTA($C9:$AF9)=0,"",SUMPRODUCT(--(UPPER(TRIM(W9:AA9))=W$5:AA$5))) | AL9: =IF(COUNTA($C9:$AF9)=0,"",SUMPRODUCT(--(UPPER(TRIM(AB9:AF9))=AB$5:AF$5))) | AM9: =IF(AG9="","",ROUND((AG9+AH9+AI9)/15*100,0)) | AN9: =IF(AG9="","",ROUND((AJ9+AK9+AL9)/15*100,0)) | AO9: =IF(AG9="","",SUM(AG9:AL9)) | AP9: =IF(AO9="","",ROUND(AO9/30*100,0)) | AQ9: =IF(AP9="","",IF(AP9>=Darajalar!$B$2,"Yuqori",IF(AP9>=Darajalar!$B$3,"Yaxshi",IF(AP9>=Darajalar!$B$4,"O‘rta","Boshlang‘ich")))) | AR9: =IF(AP9="","",ROUND(AP9/10,0)) | AS9: =IF(AM9="","",IF(AM9>=Darajalar!$B$3,"Mos",IF(AM9>=Darajalar!$B$4,"Qisman mos","Mos emas"))) | AT9: =IF(AP9="","",IF(AND(AP9>=75,OR(Amaliy!R9="",Amaliy!R9>=75)),"Ilg‘or",IF(OR(AP9<45,AND(Amaliy!R9<>"",Amaliy!R9<45)),"Yordam","Asosiy")))
A10: 5 | B10: =IF(Royxat!B6="","",Royxat!B6) | AG10: =IF(COUNTA($C10:$AF10)=0,"",SUMPRODUCT(--(UPPER(TRIM(C10:G10))=C$5:G$5))) | AH10: =IF(COUNTA($C10:$AF10)=0,"",SUMPRODUCT(--(UPPER(TRIM(H10:L10))=H$5:L$5))) | AI10: =IF(COUNTA($C10:$AF10)=0,"",SUMPRODUCT(--(UPPER(TRIM(M10:Q10))=M$5:Q$5))) | AJ10: =IF(COUNTA($C10:$AF10)=0,"",SUMPRODUCT(--(UPPER(TRIM(R10:V10))=R$5:V$5))) | AK10: =IF(COUNTA($C10:$AF10)=0,"",SUMPRODUCT(--(UPPER(TRIM(W10:AA10))=W$5:AA$5))) | AL10: =IF(COUNTA($C10:$AF10)=0,"",SUMPRODUCT(--(UPPER(TRIM(AB10:AF10))=AB$5:AF$5))) | AM10: =IF(AG10="","",ROUND((AG10+AH10+AI10)/15*100,0)) | AN10: =IF(AG10="","",ROUND((AJ10+AK10+AL10)/15*100,0)) | AO10: =IF(AG10="","",SUM(AG10:AL10)) | AP10: =IF(AO10="","",ROUND(AO10/30*100,0)) | AQ10: =IF(AP10="","",IF(AP10>=Darajalar!$B$2,"Yuqori",IF(AP10>=Darajalar!$B$3,"Yaxshi",IF(AP10>=Darajalar!$B$4,"O‘rta","Boshlang‘ich")))) | AR10: =IF(AP10="","",ROUND(AP10/10,0)) | AS10: =IF(AM10="","",IF(AM10>=Darajalar!$B$3,"Mos",IF(AM10>=Darajalar!$B$4,"Qisman mos","Mos emas"))) | AT10: =IF(AP10="","",IF(AND(AP10>=75,OR(Amaliy!R10="",Amaliy!R10>=75)),"Ilg‘or",IF(OR(AP10<45,AND(Amaliy!R10<>"",Amaliy!R10<45)),"Yordam","Asosiy")))
A11: 6 | B11: =IF(Royxat!B7="","",Royxat!B7) | AG11: =IF(COUNTA($C11:$AF11)=0,"",SUMPRODUCT(--(UPPER(TRIM(C11:G11))=C$5:G$5))) | AH11: =IF(COUNTA($C11:$AF11)=0,"",SUMPRODUCT(--(UPPER(TRIM(H11:L11))=H$5:L$5))) | AI11: =IF(COUNTA($C11:$AF11)=0,"",SUMPRODUCT(--(UPPER(TRIM(M11:Q11))=M$5:Q$5))) | AJ11: =IF(COUNTA($C11:$AF11)=0,"",SUMPRODUCT(--(UPPER(TRIM(R11:V11))=R$5:V$5))) | AK11: =IF(COUNTA($C11:$AF11)=0,"",SUMPRODUCT(--(UPPER(TRIM(W11:AA11))=W$5:AA$5))) | AL11: =IF(COUNTA($C11:$AF11)=0,"",SUMPRODUCT(--(UPPER(TRIM(AB11:AF11))=AB$5:AF$5))) | AM11: =IF(AG11="","",ROUND((AG11+AH11+AI11)/15*100,0)) | AN11: =IF(AG11="","",ROUND((AJ11+AK11+AL11)/15*100,0)) | AO11: =IF(AG11="","",SUM(AG11:AL11)) | AP11: =IF(AO11="","",ROUND(AO11/30*100,0)) | AQ11: =IF(AP11="","",IF(AP11>=Darajalar!$B$2,"Yuqori",IF(AP11>=Darajalar!$B$3,"Yaxshi",IF(AP11>=Darajalar!$B$4,"O‘rta","Boshlang‘ich")))) | AR11: =IF(AP11="","",ROUND(AP11/10,0)) | AS11: =IF(AM11="","",IF(AM11>=Darajalar!$B$3,"Mos",IF(AM11>=Darajalar!$B$4,"Qisman mos","Mos emas"))) | AT11: =IF(AP11="","",IF(AND(AP11>=75,OR(Amaliy!R11="",Amaliy!R11>=75)),"Ilg‘or",IF(OR(AP11<45,AND(Amaliy!R11<>"",Amaliy!R11<45)),"Yordam","Asosiy")))
A12: 7 | B12: =IF(Royxat!B8="","",Royxat!B8) | AG12: =IF(COUNTA($C12:$AF12)=0,"",SUMPRODUCT(--(UPPER(TRIM(C12:G12))=C$5:G$5))) | AH12: =IF(COUNTA($C12:$AF12)=0,"",SUMPRODUCT(--(UPPER(TRIM(H12:L12))=H$5:L$5))) | AI12: =IF(COUNTA($C12:$AF12)=0,"",SUMPRODUCT(--(UPPER(TRIM(M12:Q12))=M$5:Q$5))) | AJ12: =IF(COUNTA($C12:$AF12)=0,"",SUMPRODUCT(--(UPPER(TRIM(R12:V12))=R$5:V$5))) | AK12: =IF(COUNTA($C12:$AF12)=0,"",SUMPRODUCT(--(UPPER(TRIM(W12:AA12))=W$5:AA$5))) | AL12: =IF(COUNTA($C12:$AF12)=0,"",SUMPRODUCT(--(UPPER(TRIM(AB12:AF12))=AB$5:AF$5))) | AM12: =IF(AG12="","",ROUND((AG12+AH12+AI12)/15*100,0)) | AN12: =IF(AG12="","",ROUND((AJ12+AK12+AL12)/15*100,0)) | AO12: =IF(AG12="","",SUM(AG12:AL12)) | AP12: =IF(AO12="","",ROUND(AO12/30*100,0)) | AQ12: =IF(AP12="","",IF(AP12>=Darajalar!$B$2,"Yuqori",IF(AP12>=Darajalar!$B$3,"Yaxshi",IF(AP12>=Darajalar!$B$4,"O‘rta","Boshlang‘ich")))) | AR12: =IF(AP12="","",ROUND(AP12/10,0)) | AS12: =IF(AM12="","",IF(AM12>=Darajalar!$B$3,"Mos",IF(AM12>=Darajalar!$B$4,"Qisman mos","Mos emas"))) | AT12: =IF(AP12="","",IF(AND(AP12>=75,OR(Amaliy!R12="",Amaliy!R12>=75)),"Ilg‘or",IF(OR(AP12<45,AND(Amaliy!R12<>"",Amaliy!R12<45)),"Yordam","Asosiy")))
A13: 8 | B13: =IF(Royxat!B9="","",Royxat!B9) | AG13: =IF(COUNTA($C13:$AF13)=0,"",SUMPRODUCT(--(UPPER(TRIM(C13:G13))=C$5:G$5))) | AH13: =IF(COUNTA($C13:$AF13)=0,"",SUMPRODUCT(--(UPPER(TRIM(H13:L13))=H$5:L$5))) | AI13: =IF(COUNTA($C13:$AF13)=0,"",SUMPRODUCT(--(UPPER(TRIM(M13:Q13))=M$5:Q$5))) | AJ13: =IF(COUNTA($C13:$AF13)=0,"",SUMPRODUCT(--(UPPER(TRIM(R13:V13))=R$5:V$5))) | AK13: =IF(COUNTA($C13:$AF13)=0,"",SUMPRODUCT(--(UPPER(TRIM(W13:AA13))=W$5:AA$5))) | AL13: =IF(COUNTA($C13:$AF13)=0,"",SUMPRODUCT(--(UPPER(TRIM(AB13:AF13))=AB$5:AF$5))) | AM13: =IF(AG13="","",ROUND((AG13+AH13+AI13)/15*100,0)) | AN13: =IF(AG13="","",ROUND((AJ13+AK13+AL13)/15*100,0)) | AO13: =IF(AG13="","",SUM(AG13:AL13)) | AP13: =IF(AO13="","",ROUND(AO13/30*100,0)) | AQ13: =IF(AP13="","",IF(AP13>=Darajalar!$B$2,"Yuqori",IF(AP13>=Darajalar!$B$3,"Yaxshi",IF(AP13>=Darajalar!$B$4,"O‘rta","Boshlang‘ich")))) | AR13: =IF(AP13="","",ROUND(AP13/10,0)) | AS13: =IF(AM13="","",IF(AM13>=Darajalar!$B$3,"Mos",IF(AM13>=Darajalar!$B$4,"Qisman mos","Mos emas"))) | AT13: =IF(AP13="","",IF(AND(AP13>=75,OR(Amaliy!R13="",Amaliy!R13>=75)),"Ilg‘or",IF(OR(AP13<45,AND(Amaliy!R13<>"",Amaliy!R13<45)),"Yordam","Asosiy")))
A14: 9 | B14: =IF(Royxat!B10="","",Royxat!B10) | AG14: =IF(COUNTA($C14:$AF14)=0,"",SUMPRODUCT(--(UPPER(TRIM(C14:G14))=C$5:G$5))) | AH14: =IF(COUNTA($C14:$AF14)=0,"",SUMPRODUCT(--(UPPER(TRIM(H14:L14))=H$5:L$5))) | AI14: =IF(COUNTA($C14:$AF14)=0,"",SUMPRODUCT(--(UPPER(TRIM(M14:Q14))=M$5:Q$5))) | AJ14: =IF(COUNTA($C14:$AF14)=0,"",SUMPRODUCT(--(UPPER(TRIM(R14:V14))=R$5:V$5))) | AK14: =IF(COUNTA($C14:$AF14)=0,"",SUMPRODUCT(--(UPPER(TRIM(W14:AA14))=W$5:AA$5))) | AL14: =IF(COUNTA($C14:$AF14)=0,"",SUMPRODUCT(--(UPPER(TRIM(AB14:AF14))=AB$5:AF$5))) | AM14: =IF(AG14="","",ROUND((AG14+AH14+AI14)/15*100,0)) | AN14: =IF(AG14="","",ROUND((AJ14+AK14+AL14)/15*100,0)) | AO14: =IF(AG14="","",SUM(AG14:AL14)) | AP14: =IF(AO14="","",ROUND(AO14/30*100,0)) | AQ14: =IF(AP14="","",IF(AP14>=Darajalar!$B$2,"Yuqori",IF(AP14>=Darajalar!$B$3,"Yaxshi",IF(AP14>=Darajalar!$B$4,"O‘rta","Boshlang‘ich")))) | AR14: =IF(AP14="","",ROUND(AP14/10,0)) | AS14: =IF(AM14="","",IF(AM14>=Darajalar!$B$3,"Mos",IF(AM14>=Darajalar!$B$4,"Qisman mos","Mos emas"))) | AT14: =IF(AP14="","",IF(AND(AP14>=75,OR(Amaliy!R14="",Amaliy!R14>=75)),"Ilg‘or",IF(OR(AP14<45,AND(Amaliy!R14<>"",Amaliy!R14<45)),"Yordam","Asosiy")))
A15: 10 | B15: =IF(Royxat!B11="","",Royxat!B11) | AG15: =IF(COUNTA($C15:$AF15)=0,"",SUMPRODUCT(--(UPPER(TRIM(C15:G15))=C$5:G$5))) | AH15: =IF(COUNTA($C15:$AF15)=0,"",SUMPRODUCT(--(UPPER(TRIM(H15:L15))=H$5:L$5))) | AI15: =IF(COUNTA($C15:$AF15)=0,"",SUMPRODUCT(--(UPPER(TRIM(M15:Q15))=M$5:Q$5))) | AJ15: =IF(COUNTA($C15:$AF15)=0,"",SUMPRODUCT(--(UPPER(TRIM(R15:V15))=R$5:V$5))) | AK15: =IF(COUNTA($C15:$AF15)=0,"",SUMPRODUCT(--(UPPER(TRIM(W15:AA15))=W$5:AA$5))) | AL15: =IF(COUNTA($C15:$AF15)=0,"",SUMPRODUCT(--(UPPER(TRIM(AB15:AF15))=AB$5:AF$5))) | AM15: =IF(AG15="","",ROUND((AG15+AH15+AI15)/15*100,0)) | AN15: =IF(AG15="","",ROUND((AJ15+AK15+AL15)/15*100,0)) | AO15: =IF(AG15="","",SUM(AG15:AL15)) | AP15: =IF(AO15="","",ROUND(AO15/30*100,0)) | AQ15: =IF(AP15="","",IF(AP15>=Darajalar!$B$2,"Yuqori",IF(AP15>=Darajalar!$B$3,"Yaxshi",IF(AP15>=Darajalar!$B$4,"O‘rta","Boshlang‘ich")))) | AR15: =IF(AP15="","",ROUND(AP15/10,0)) | AS15: =IF(AM15="","",IF(AM15>=Darajalar!$B$3,"Mos",IF(AM15>=Darajalar!$B$4,"Qisman mos","Mos emas"))) | AT15: =IF(AP15="","",IF(AND(AP15>=75,OR(Amaliy!R15="",Amaliy!R15>=75)),"Ilg‘or",IF(OR(AP15<45,AND(Amaliy!R15<>"",Amaliy!R15<45)),"Yordam","Asosiy")))
A16: 11 | B16: =IF(Royxat!B12="","",Royxat!B12) | AG16: =IF(COUNTA($C16:$AF16)=0,"",SUMPRODUCT(--(UPPER(TRIM(C16:G16))=C$5:G$5))) | AH16: =IF(COUNTA($C16:$AF16)=0,"",SUMPRODUCT(--(UPPER(TRIM(H16:L16))=H$5:L$5))) | AI16: =IF(COUNTA($C16:$AF16)=0,"",SUMPRODUCT(--(UPPER(TRIM(M16:Q16))=M$5:Q$5))) | AJ16: =IF(COUNTA($C16:$AF16)=0,"",SUMPRODUCT(--(UPPER(TRIM(R16:V16))=R$5:V$5))) | AK16: =IF(COUNTA($C16:$AF16)=0,"",SUMPRODUCT(--(UPPER(TRIM(W16:AA16))=W$5:AA$5))) | AL16: =IF(COUNTA($C16:$AF16)=0,"",SUMPRODUCT(--(UPPER(TRIM(AB16:AF16))=AB$5:AF$5))) | AM16: =IF(AG16="","",ROUND((AG16+AH16+AI16)/15*100,0)) | AN16: =IF(AG16="","",ROUND((AJ16+AK16+AL16)/15*100,0)) | AO16: =IF(AG16="","",SUM(AG16:AL16)) | AP16: =IF(AO16="","",ROUND(AO16/30*100,0)) | AQ16: =IF(AP16="","",IF(AP16>=Darajalar!$B$2,"Yuqori",IF(AP16>=Darajalar!$B$3,"Yaxshi",IF(AP16>=Darajalar!$B$4,"O‘rta","Boshlang‘ich")))) | AR16: =IF(AP16="","",ROUND(AP16/10,0)) | AS16: =IF(AM16="","",IF(AM16>=Darajalar!$B$3,"Mos",IF(AM16>=Darajalar!$B$4,"Qisman mos","Mos emas"))) | AT16: =IF(AP16="","",IF(AND(AP16>=75,OR(Amaliy!R16="",Amaliy!R16>=75)),"Ilg‘or",IF(OR(AP16<45,AND(Amaliy!R16<>"",Amaliy!R16<45)),"Yordam","Asosiy")))
A17: 12 | B17: =IF(Royxat!B13="","",Royxat!B13) | AG17: =IF(COUNTA($C17:$AF17)=0,"",SUMPRODUCT(--(UPPER(TRIM(C17:G17))=C$5:G$5))) | AH17: =IF(COUNTA($C17:$AF17)=0,"",SUMPRODUCT(--(UPPER(TRIM(H17:L17))=H$5:L$5))) | AI17: =IF(COUNTA($C17:$AF17)=0,"",SUMPRODUCT(--(UPPER(TRIM(M17:Q17))=M$5:Q$5))) | AJ17: =IF(COUNTA($C17:$AF17)=0,"",SUMPRODUCT(--(UPPER(TRIM(R17:V17))=R$5:V$5))) | AK17: =IF(COUNTA($C17:$AF17)=0,"",SUMPRODUCT(--(UPPER(TRIM(W17:AA17))=W$5:AA$5))) | AL17: =IF(COUNTA($C17:$AF17)=0,"",SUMPRODUCT(--(UPPER(TRIM(AB17:AF17))=AB$5:AF$5))) | AM17: =IF(AG17="","",ROUND((AG17+AH17+AI17)/15*100,0)) | AN17: =IF(AG17="","",ROUND((AJ17+AK17+AL17)/15*100,0)) | AO17: =IF(AG17="","",SUM(AG17:AL17)) | AP17: =IF(AO17="","",ROUND(AO17/30*100,0)) | AQ17: =IF(AP17="","",IF(AP17>=Darajalar!$B$2,"Yuqori",IF(AP17>=Darajalar!$B$3,"Yaxshi",IF(AP17>=Darajalar!$B$4,"O‘rta","Boshlang‘ich")))) | AR17: =IF(AP17="","",ROUND(AP17/10,0)) | AS17: =IF(AM17="","",IF(AM17>=Darajalar!$B$3,"Mos",IF(AM17>=Darajalar!$B$4,"Qisman mos","Mos emas"))) | AT17: =IF(AP17="","",IF(AND(AP17>=75,OR(Amaliy!R17="",Amaliy!R17>=75)),"Ilg‘or",IF(OR(AP17<45,AND(Amaliy!R17<>"",Amaliy!R17<45)),"Yordam","Asosiy")))
... A40: 35 | B40: =IF(Royxat!B36="","",Royxat!B36) | AG40: =IF(COUNTA($C40:$AF40)=0,"",SUMPRODUCT(--(UPPER(TRIM(C40:G40))=C$5:G$5))) | AH40: =IF(COUNTA($C40:$AF40)=0,"",SUMPRODUCT(--(UPPER(TRIM(H40:L40))=H$5:L$5))) | AI40: =IF(COUNTA($C40:$AF40)=0,"",SUMPRODUCT(--(UPPER(TRIM(M40:Q40))=M$5:Q$5))) | AJ40: =IF(COUNTA($C40:$AF40)=0,"",SUMPRODUCT(--(UPPER(TRIM(R40:V40))=R$5:V$5))) | AK40: =IF(COUNTA($C40:$AF40)=0,"",SUMPRODUCT(--(UPPER(TRIM(W40:AA40))=W$5:AA$5))) | AL40: =IF(COUNTA($C40:$AF40)=0,"",SUMPRODUCT(--(UPPER(TRIM(AB40:AF40))=AB$5:AF$5))) | AM40: =IF(AG40="","",ROUND((AG40+AH40+AI40)/15*100,0)) | AN40: =IF(AG40="","",ROUND((AJ40+AK40+AL40)/15*100,0)) | AO40: =IF(AG40="","",SUM(AG40:AL40)) | AP40: =IF(AO40="","",ROUND(AO40/30*100,0)) | AQ40: =IF(AP40="","",IF(AP40>=Darajalar!$B$2,"Yuqori",IF(AP40>=Darajalar!$B$3,"Yaxshi",IF(AP40>=Darajalar!$B$4,"O‘rta","Boshlang‘ich")))) | AR40: =IF(AP40="","",ROUND(AP40/10,0)) | AS40: =IF(AM40="","",IF(AM40>=Darajalar!$B$3,"Mos",IF(AM40>=Darajalar!$B$4,"Qisman mos","Mos emas"))) | AT40: =IF(AP40="","",IF(AND(AP40>=75,OR(Amaliy!R40="",Amaliy!R40>=75)),"Ilg‘or",IF(OR(AP40<45,AND(Amaliy!R40<>"",Amaliy!R40<45)),"Yordam","Asosiy")))
B42: Sinf o‘rtacha | AG42: =IFERROR(ROUND(AVERAGE(AG6:AG40),1),"") | AH42: =IFERROR(ROUND(AVERAGE(AH6:AH40),1),"") | AI42: =IFERROR(ROUND(AVERAGE(AI6:AI40),1),"") | AJ42: =IFERROR(ROUND(AVERAGE(AJ6:AJ40),1),"") | AK42: =IFERROR(ROUND(AVERAGE(AK6:AK40),1),"") | AL42: =IFERROR(ROUND(AVERAGE(AL6:AL40),1),"") | AM42: =IFERROR(ROUND(AVERAGE(AM6:AM40),1),"") | AN42: =IFERROR(ROUND(AVERAGE(AN6:AN40),1),"") | ... AP42: =IFERROR(ROUND(AVERAGE(AP6:AP40),1),"") | AR42: =IFERROR(ROUND(AVERAGE(AR6:AR40),1),"")
B43: Savol bo‘yicha to‘g‘ri % | C43: =IF(COUNT($AP$6:$AP$40)=0,"",ROUND(SUMPRODUCT(--(UPPER(TRIM(C$6:C$40))=C$5))/COUNT($AP$6:$AP$40)*100,0)) | D43: =IF(COUNT($AP$6:$AP$40)=0,"",ROUND(SUMPRODUCT(--(UPPER(TRIM(D$6:D$40))=D$5))/COUNT($AP$6:$AP$40)*100,0)) | E43: =IF(COUNT($AP$6:$AP$40)=0,"",ROUND(SUMPRODUCT(--(UPPER(TRIM(E$6:E$40))=E$5))/COUNT($AP$6:$AP$40)*100,0)) | F43: =IF(COUNT($AP$6:$AP$40)=0,"",ROUND(SUMPRODUCT(--(UPPER(TRIM(F$6:F$40))=F$5))/COUNT($AP$6:$AP$40)*100,0)) | G43: =IF(COUNT($AP$6:$AP$40)=0,"",ROUND(SUMPRODUCT(--(UPPER(TRIM(G$6:G$40))=G$5))/COUNT($AP$6:$AP$40)*100,0)) | H43: =IF(COUNT($AP$6:$AP$40)=0,"",ROUND(SUMPRODUCT(--(UPPER(TRIM(H$6:H$40))=H$5))/COUNT($AP$6:$AP$40)*100,0)) | I43: =IF(COUNT($AP$6:$AP$40)=0,"",ROUND(SUMPRODUCT(--(UPPER(TRIM(I$6:I$40))=I$5))/COUNT($AP$6:$AP$40)*100,0)) | J43: =IF(COUNT($AP$6:$AP$40)=0,"",ROUND(SUMPRODUCT(--(UPPER(TRIM(J$6:J$40))=J$5))/COUNT($AP$6:$AP$40)*100,0)) | ... AF43: =IF(COUNT($AP$6:$AP$40)=0,"",ROUND(SUMPRODUCT(--(UPPER(TRIM(AF$6:AF$40))=AF$5))/COUNT($AP$6:$AP$40)*100,0))
B44: 40 % dan past (qizil) savollar — butun sinf uchun qiyin mavzu.

Sheet Solishtirish
A1: 7A — Oktabr (A) ↔ Yanvar (B) solishtirish. Bu varaq to‘liq avtomatik (faqat NB soni va Izohni yozasiz).
U3: SINF XULOSASI
A4: № | B4: F.I.Sh. | C4: A: Jami % | D4: B: Jami % | E4: O‘sish Δ | F4: g | G4: Daraja (okt) | H4: Daraja (yan) | I4: O‘zgarish | J4: Δ talqini | K4: Tayanch A | L4: Tayanch B | M4: 7-sinf A | N4: 7-sinf B | O4: Amaliy okt | P4: Amaliy yan | Q4: Guruh (okt) | R4: NB soni | S4: Izoh | U4: Ko‘rsatkich | V4: Oktabr (A) | W4: Yanvar (B) | X4: O‘zgarish
U5: Qatnashganlar | V5: =COUNT(C6:C40) | W5: =COUNT(D6:D40) | X5: =IFERROR(IF(OR(V5="",W5=""),"",W5-V5),"")
A6: 1 | B6: =IF(Royxat!B2="","",Royxat!B2) | C6: =A_kirish!AP6 | D6: =B_yakuniy!AP6 | E6: =IF(OR(C6="",D6=""),"",D6-C6) | F6: =IF(OR(C6="",D6=""),"",IF(C6>=100,"—",ROUND((D6-C6)/(100-C6),2))) | G6: =A_kirish!AQ6 | H6: =B_yakuniy!AQ6 | I6: =IF(OR(G6="",H6=""),"",IF(MATCH(H6,Darajalar!$A$2:$A$5,0)<MATCH(G6,Darajalar!$A$2:$A$5,0),"↑",IF(MATCH(H6,Darajalar!$A$2:$A$5,0)=MATCH(G6,Darajalar!$A$2:$A$5,0),"=","↓"))) | J6: =IF(E6="","",IF(ABS(E6)<=7,"o‘zgarishsiz (±2 savol)",IF(E6>0,"o‘sdi","pasaydi"))) | K6: =A_kirish!AM6 | L6: =B_yakuniy!AM6 | M6: =A_kirish!AN6 | N6: =B_yakuniy!AN6 | O6: =Amaliy!J6 | P6: =Amaliy!R6 | Q6: =A_kirish!AT6 | U6: O‘rtacha Jami % | V6: =IFERROR(ROUND(AVERAGE(C6:C40),1),"") | W6: =IFERROR(ROUND(AVERAGE(D6:D40),1),"") | X6: =IFERROR(IF(OR(V6="",W6=""),"",W6-V6),"")
A7: 2 | B7: =IF(Royxat!B3="","",Royxat!B3) | C7: =A_kirish!AP7 | D7: =B_yakuniy!AP7 | E7: =IF(OR(C7="",D7=""),"",D7-C7) | F7: =IF(OR(C7="",D7=""),"",IF(C7>=100,"—",ROUND((D7-C7)/(100-C7),2))) | G7: =A_kirish!AQ7 | H7: =B_yakuniy!AQ7 | I7: =IF(OR(G7="",H7=""),"",IF(MATCH(H7,Darajalar!$A$2:$A$5,0)<MATCH(G7,Darajalar!$A$2:$A$5,0),"↑",IF(MATCH(H7,Darajalar!$A$2:$A$5,0)=MATCH(G7,Darajalar!$A$2:$A$5,0),"=","↓"))) | J7: =IF(E7="","",IF(ABS(E7)<=7,"o‘zgarishsiz (±2 savol)",IF(E7>0,"o‘sdi","pasaydi"))) | K7: =A_kirish!AM7 | L7: =B_yakuniy!AM7 | M7: =A_kirish!AN7 | N7: =B_yakuniy!AN7 | O7: =Amaliy!J7 | P7: =Amaliy!R7 | Q7: =A_kirish!AT7 | U7: Median % | V7: =IF(COUNT(C6:C40)=0,"",MEDIAN(C6:C40)) | W7: =IF(COUNT(D6:D40)=0,"",MEDIAN(D6:D40)) | X7: =IFERROR(IF(OR(V7="",W7=""),"",W7-V7),"")
A8: 3 | B8: =IF(Royxat!B4="","",Royxat!B4) | C8: =A_kirish!AP8 | D8: =B_yakuniy!AP8 | E8: =IF(OR(C8="",D8=""),"",D8-C8) | F8: =IF(OR(C8="",D8=""),"",IF(C8>=100,"—",ROUND((D8-C8)/(100-C8),2))) | G8: =A_kirish!AQ8 | H8: =B_yakuniy!AQ8 | I8: =IF(OR(G8="",H8=""),"",IF(MATCH(H8,Darajalar!$A$2:$A$5,0)<MATCH(G8,Darajalar!$A$2:$A$5,0),"↑",IF(MATCH(H8,Darajalar!$A$2:$A$5,0)=MATCH(G8,Darajalar!$A$2:$A$5,0),"=","↓"))) | J8: =IF(E8="","",IF(ABS(E8)<=7,"o‘zgarishsiz (±2 savol)",IF(E8>0,"o‘sdi","pasaydi"))) | K8: =A_kirish!AM8 | L8: =B_yakuniy!AM8 | M8: =A_kirish!AN8 | N8: =B_yakuniy!AN8 | O8: =Amaliy!J8 | P8: =Amaliy!R8 | Q8: =A_kirish!AT8 | U8: Eng past % | V8: =IF(COUNT(C6:C40)=0,"",MIN(C6:C40)) | W8: =IF(COUNT(D6:D40)=0,"",MIN(D6:D40)) | X8: =IFERROR(IF(OR(V8="",W8=""),"",W8-V8),"")
A9: 4 | B9: =IF(Royxat!B5="","",Royxat!B5) | C9: =A_kirish!AP9 | D9: =B_yakuniy!AP9 | E9: =IF(OR(C9="",D9=""),"",D9-C9) | F9: =IF(OR(C9="",D9=""),"",IF(C9>=100,"—",ROUND((D9-C9)/(100-C9),2))) | G9: =A_kirish!AQ9 | H9: =B_yakuniy!AQ9 | I9: =IF(OR(G9="",H9=""),"",IF(MATCH(H9,Darajalar!$A$2:$A$5,0)<MATCH(G9,Darajalar!$A$2:$A$5,0),"↑",IF(MATCH(H9,Darajalar!$A$2:$A$5,0)=MATCH(G9,Darajalar!$A$2:$A$5,0),"=","↓"))) | J9: =IF(E9="","",IF(ABS(E9)<=7,"o‘zgarishsiz (±2 savol)",IF(E9>0,"o‘sdi","pasaydi"))) | K9: =A_kirish!AM9 | L9: =B_yakuniy!AM9 | M9: =A_kirish!AN9 | N9: =B_yakuniy!AN9 | O9: =Amaliy!J9 | P9: =Amaliy!R9 | Q9: =A_kirish!AT9 | U9: Eng yuqori % | V9: =IF(COUNT(C6:C40)=0,"",MAX(C6:C40)) | W9: =IF(COUNT(D6:D40)=0,"",MAX(D6:D40)) | X9: =IFERROR(IF(OR(V9="",W9=""),"",W9-V9),"")
A10: 5 | B10: =IF(Royxat!B6="","",Royxat!B6) | C10: =A_kirish!AP10 | D10: =B_yakuniy!AP10 | E10: =IF(OR(C10="",D10=""),"",D10-C10) | F10: =IF(OR(C10="",D10=""),"",IF(C10>=100,"—",ROUND((D10-C10)/(100-C10),2))) | G10: =A_kirish!AQ10 | H10: =B_yakuniy!AQ10 | I10: =IF(OR(G10="",H10=""),"",IF(MATCH(H10,Darajalar!$A$2:$A$5,0)<MATCH(G10,Darajalar!$A$2:$A$5,0),"↑",IF(MATCH(H10,Darajalar!$A$2:$A$5,0)=MATCH(G10,Darajalar!$A$2:$A$5,0),"=","↓"))) | J10: =IF(E10="","",IF(ABS(E10)<=7,"o‘zgarishsiz (±2 savol)",IF(E10>0,"o‘sdi","pasaydi"))) | K10: =A_kirish!AM10 | L10: =B_yakuniy!AM10 | M10: =A_kirish!AN10 | N10: =B_yakuniy!AN10 | O10: =Amaliy!J10 | P10: =Amaliy!R10 | Q10: =A_kirish!AT10 | U10: Tayanch % (S1–S3) | V10: =IFERROR(ROUND(AVERAGE(K6:K40),1),"") | W10: =IFERROR(ROUND(AVERAGE(L6:L40),1),"") | X10: =IFERROR(IF(OR(V10="",W10=""),"",W10-V10),"")
A11: 6 | B11: =IF(Royxat!B7="","",Royxat!B7) | C11: =A_kirish!AP11 | D11: =B_yakuniy!AP11 | E11: =IF(OR(C11="",D11=""),"",D11-C11) | F11: =IF(OR(C11="",D11=""),"",IF(C11>=100,"—",ROUND((D11-C11)/(100-C11),2))) | G11: =A_kirish!AQ11 | H11: =B_yakuniy!AQ11 | I11: =IF(OR(G11="",H11=""),"",IF(MATCH(H11,Darajalar!$A$2:$A$5,0)<MATCH(G11,Darajalar!$A$2:$A$5,0),"↑",IF(MATCH(H11,Darajalar!$A$2:$A$5,0)=MATCH(G11,Darajalar!$A$2:$A$5,0),"=","↓"))) | J11: =IF(E11="","",IF(ABS(E11)<=7,"o‘zgarishsiz (±2 savol)",IF(E11>0,"o‘sdi","pasaydi"))) | K11: =A_kirish!AM11 | L11: =B_yakuniy!AM11 | M11: =A_kirish!AN11 | N11: =B_yakuniy!AN11 | O11: =Amaliy!J11 | P11: =Amaliy!R11 | Q11: =A_kirish!AT11 | U11: 7-sinf % (S4–S6) | V11: =IFERROR(ROUND(AVERAGE(M6:M40),1),"") | W11: =IFERROR(ROUND(AVERAGE(N6:N40),1),"") | X11: =IFERROR(IF(OR(V11="",W11=""),"",W11-V11),"")
A12: 7 | B12: =IF(Royxat!B8="","",Royxat!B8) | C12: =A_kirish!AP12 | D12: =B_yakuniy!AP12 | E12: =IF(OR(C12="",D12=""),"",D12-C12) | F12: =IF(OR(C12="",D12=""),"",IF(C12>=100,"—",ROUND((D12-C12)/(100-C12),2))) | G12: =A_kirish!AQ12 | H12: =B_yakuniy!AQ12 | I12: =IF(OR(G12="",H12=""),"",IF(MATCH(H12,Darajalar!$A$2:$A$5,0)<MATCH(G12,Darajalar!$A$2:$A$5,0),"↑",IF(MATCH(H12,Darajalar!$A$2:$A$5,0)=MATCH(G12,Darajalar!$A$2:$A$5,0),"=","↓"))) | J12: =IF(E12="","",IF(ABS(E12)<=7,"o‘zgarishsiz (±2 savol)",IF(E12>0,"o‘sdi","pasaydi"))) | K12: =A_kirish!AM12 | L12: =B_yakuniy!AM12 | M12: =A_kirish!AN12 | N12: =B_yakuniy!AN12 | O12: =Amaliy!J12 | P12: =Amaliy!R12 | Q12: =A_kirish!AT12 | U12: Amaliy % | V12: =IFERROR(ROUND(AVERAGE(O6:O40),1),"") | W12: =IFERROR(ROUND(AVERAGE(P6:P40),1),"") | X12: =IFERROR(IF(OR(V12="",W12=""),"",W12-V12),"")
A13: 8 | B13: =IF(Royxat!B9="","",Royxat!B9) | C13: =A_kirish!AP13 | D13: =B_yakuniy!AP13 | E13: =IF(OR(C13="",D13=""),"",D13-C13) | F13: =IF(OR(C13="",D13=""),"",IF(C13>=100,"—",ROUND((D13-C13)/(100-C13),2))) | G13: =A_kirish!AQ13 | H13: =B_yakuniy!AQ13 | I13: =IF(OR(G13="",H13=""),"",IF(MATCH(H13,Darajalar!$A$2:$A$5,0)<MATCH(G13,Darajalar!$A$2:$A$5,0),"↑",IF(MATCH(H13,Darajalar!$A$2:$A$5,0)=MATCH(G13,Darajalar!$A$2:$A$5,0),"=","↓"))) | J13: =IF(E13="","",IF(ABS(E13)<=7,"o‘zgarishsiz (±2 savol)",IF(E13>0,"o‘sdi","pasaydi"))) | K13: =A_kirish!AM13 | L13: =B_yakuniy!AM13 | M13: =A_kirish!AN13 | N13: =B_yakuniy!AN13 | O13: =Amaliy!J13 | P13: =Amaliy!R13 | Q13: =A_kirish!AT13 | U13: Yuqori (soni) | V13: =COUNTIF(G6:G40,"Yuqori") | W13: =COUNTIF(H6:H40,"Yuqori") | X13: =IFERROR(IF(OR(V13="",W13=""),"",W13-V13),"")
A14: 9 | B14: =IF(Royxat!B10="","",Royxat!B10) | C14: =A_kirish!AP14 | D14: =B_yakuniy!AP14 | E14: =IF(OR(C14="",D14=""),"",D14-C14) | F14: =IF(OR(C14="",D14=""),"",IF(C14>=100,"—",ROUND((D14-C14)/(100-C14),2))) | G14: =A_kirish!AQ14 | H14: =B_yakuniy!AQ14 | I14: =IF(OR(G14="",H14=""),"",IF(MATCH(H14,Darajalar!$A$2:$A$5,0)<MATCH(G14,Darajalar!$A$2:$A$5,0),"↑",IF(MATCH(H14,Darajalar!$A$2:$A$5,0)=MATCH(G14,Darajalar!$A$2:$A$5,0),"=","↓"))) | J14: =IF(E14="","",IF(ABS(E14)<=7,"o‘zgarishsiz (±2 savol)",IF(E14>0,"o‘sdi","pasaydi"))) | K14: =A_kirish!AM14 | L14: =B_yakuniy!AM14 | M14: =A_kirish!AN14 | N14: =B_yakuniy!AN14 | O14: =Amaliy!J14 | P14: =Amaliy!R14 | Q14: =A_kirish!AT14 | U14: Yaxshi (soni) | V14: =COUNTIF(G6:G40,"Yaxshi") | W14: =COUNTIF(H6:H40,"Yaxshi") | X14: =IFERROR(IF(OR(V14="",W14=""),"",W14-V14),"")
A15: 10 | B15: =IF(Royxat!B11="","",Royxat!B11) | C15: =A_kirish!AP15 | D15: =B_yakuniy!AP15 | E15: =IF(OR(C15="",D15=""),"",D15-C15) | F15: =IF(OR(C15="",D15=""),"",IF(C15>=100,"—",ROUND((D15-C15)/(100-C15),2))) | G15: =A_kirish!AQ15 | H15: =B_yakuniy!AQ15 | I15: =IF(OR(G15="",H15=""),"",IF(MATCH(H15,Darajalar!$A$2:$A$5,0)<MATCH(G15,Darajalar!$A$2:$A$5,0),"↑",IF(MATCH(H15,Darajalar!$A$2:$A$5,0)=MATCH(G15,Darajalar!$A$2:$A$5,0),"=","↓"))) | J15: =IF(E15="","",IF(ABS(E15)<=7,"o‘zgarishsiz (±2 savol)",IF(E15>0,"o‘sdi","pasaydi"))) | K15: =A_kirish!AM15 | L15: =B_yakuniy!AM15 | M15: =A_kirish!AN15 | N15: =B_yakuniy!AN15 | O15: =Amaliy!J15 | P15: =Amaliy!R15 | Q15: =A_kirish!AT15 | U15: O‘rta (soni) | V15: =COUNTIF(G6:G40,"O‘rta") | W15: =COUNTIF(H6:H40,"O‘rta") | X15: =IFERROR(IF(OR(V15="",W15=""),"",W15-V15),"")
A16: 11 | B16: =IF(Royxat!B12="","",Royxat!B12) | C16: =A_kirish!AP16 | D16: =B_yakuniy!AP16 | E16: =IF(OR(C16="",D16=""),"",D16-C16) | F16: =IF(OR(C16="",D16=""),"",IF(C16>=100,"—",ROUND((D16-C16)/(100-C16),2))) | G16: =A_kirish!AQ16 | H16: =B_yakuniy!AQ16 | I16: =IF(OR(G16="",H16=""),"",IF(MATCH(H16,Darajalar!$A$2:$A$5,0)<MATCH(G16,Darajalar!$A$2:$A$5,0),"↑",IF(MATCH(H16,Darajalar!$A$2:$A$5,0)=MATCH(G16,Darajalar!$A$2:$A$5,0),"=","↓"))) | J16: =IF(E16="","",IF(ABS(E16)<=7,"o‘zgarishsiz (±2 savol)",IF(E16>0,"o‘sdi","pasaydi"))) | K16: =A_kirish!AM16 | L16: =B_yakuniy!AM16 | M16: =A_kirish!AN16 | N16: =B_yakuniy!AN16 | O16: =Amaliy!J16 | P16: =Amaliy!R16 | Q16: =A_kirish!AT16 | U16: Boshlang‘ich (soni) | V16: =COUNTIF(G6:G40,"Boshlang‘ich") | W16: =COUNTIF(H6:H40,"Boshlang‘ich") | X16: =IFERROR(IF(OR(V16="",W16=""),"",W16-V16),"")
A17: 12 | B17: =IF(Royxat!B13="","",Royxat!B13) | C17: =A_kirish!AP17 | D17: =B_yakuniy!AP17 | E17: =IF(OR(C17="",D17=""),"",D17-C17) | F17: =IF(OR(C17="",D17=""),"",IF(C17>=100,"—",ROUND((D17-C17)/(100-C17),2))) | G17: =A_kirish!AQ17 | H17: =B_yakuniy!AQ17 | I17: =IF(OR(G17="",H17=""),"",IF(MATCH(H17,Darajalar!$A$2:$A$5,0)<MATCH(G17,Darajalar!$A$2:$A$5,0),"↑",IF(MATCH(H17,Darajalar!$A$2:$A$5,0)=MATCH(G17,Darajalar!$A$2:$A$5,0),"=","↓"))) | J17: =IF(E17="","",IF(ABS(E17)<=7,"o‘zgarishsiz (±2 savol)",IF(E17>0,"o‘sdi","pasaydi"))) | K17: =A_kirish!AM17 | L17: =B_yakuniy!AM17 | M17: =A_kirish!AN17 | N17: =B_yakuniy!AN17 | O17: =Amaliy!J17 | P17: =Amaliy!R17 | Q17: =A_kirish!AT17 | U17: 7-sinfga «Mos» (soni) | V17: =COUNTIF(A_kirish!AS6:AS40,"Mos") | W17: =COUNTIF(B_yakuniy!AS6:AS40,"Mos") | X17: =IFERROR(IF(OR(V17="",W17=""),"",W17-V17),"")
A18: 13 | B18: =IF(Royxat!B14="","",Royxat!B14) | C18: =A_kirish!AP18 | D18: =B_yakuniy!AP18 | E18: =IF(OR(C18="",D18=""),"",D18-C18) | F18: =IF(OR(C18="",D18=""),"",IF(C18>=100,"—",ROUND((D18-C18)/(100-C18),2))) | G18: =A_kirish!AQ18 | H18: =B_yakuniy!AQ18 | I18: =IF(OR(G18="",H18=""),"",IF(MATCH(H18,Darajalar!$A$2:$A$5,0)<MATCH(G18,Darajalar!$A$2:$A$5,0),"↑",IF(MATCH(H18,Darajalar!$A$2:$A$5,0)=MATCH(G18,Darajalar!$A$2:$A$5,0),"=","↓"))) | J18: =IF(E18="","",IF(ABS(E18)<=7,"o‘zgarishsiz (±2 savol)",IF(E18>0,"o‘sdi","pasaydi"))) | K18: =A_kirish!AM18 | L18: =B_yakuniy!AM18 | M18: =A_kirish!AN18 | N18: =B_yakuniy!AN18 | O18: =Amaliy!J18 | P18: =Amaliy!R18 | Q18: =A_kirish!AT18
A19: 14 | B19: =IF(Royxat!B15="","",Royxat!B15) | C19: =A_kirish!AP19 | D19: =B_yakuniy!AP19 | E19: =IF(OR(C19="",D19=""),"",D19-C19) | F19: =IF(OR(C19="",D19=""),"",IF(C19>=100,"—",ROUND((D19-C19)/(100-C19),2))) | G19: =A_kirish!AQ19 | H19: =B_yakuniy!AQ19 | I19: =IF(OR(G19="",H19=""),"",IF(MATCH(H19,Darajalar!$A$2:$A$5,0)<MATCH(G19,Darajalar!$A$2:$A$5,0),"↑",IF(MATCH(H19,Darajalar!$A$2:$A$5,0)=MATCH(G19,Darajalar!$A$2:$A$5,0),"=","↓"))) | J19: =IF(E19="","",IF(ABS(E19)<=7,"o‘zgarishsiz (±2 savol)",IF(E19>0,"o‘sdi","pasaydi"))) | K19: =A_kirish!AM19 | L19: =B_yakuniy!AM19 | M19: =A_kirish!AN19 | N19: =B_yakuniy!AN19 | O19: =Amaliy!J19 | P19: =Amaliy!R19 | Q19: =A_kirish!AT19 | U19: O‘SISH (faqat ikkala testda qatnashganlar)
A20: 15 | B20: =IF(Royxat!B16="","",Royxat!B16) | C20: =A_kirish!AP20 | D20: =B_yakuniy!AP20 | E20: =IF(OR(C20="",D20=""),"",D20-C20) | F20: =IF(OR(C20="",D20=""),"",IF(C20>=100,"—",ROUND((D20-C20)/(100-C20),2))) | G20: =A_kirish!AQ20 | H20: =B_yakuniy!AQ20 | I20: =IF(OR(G20="",H20=""),"",IF(MATCH(H20,Darajalar!$A$2:$A$5,0)<MATCH(G20,Darajalar!$A$2:$A$5,0),"↑",IF(MATCH(H20,Darajalar!$A$2:$A$5,0)=MATCH(G20,Darajalar!$A$2:$A$5,0),"=","↓"))) | J20: =IF(E20="","",IF(ABS(E20)<=7,"o‘zgarishsiz (±2 savol)",IF(E20>0,"o‘sdi","pasaydi"))) | K20: =A_kirish!AM20 | L20: =B_yakuniy!AM20 | M20: =A_kirish!AN20 | N20: =B_yakuniy!AN20 | O20: =Amaliy!J20 | P20: =Amaliy!R20 | Q20: =A_kirish!AT20 | U20: Juftliklar soni | V20: =SUMPRODUCT(--(C6:C40<>""),--(D6:D40<>""))
A21: 16 | B21: =IF(Royxat!B17="","",Royxat!B17) | C21: =A_kirish!AP21 | D21: =B_yakuniy!AP21 | E21: =IF(OR(C21="",D21=""),"",D21-C21) | F21: =IF(OR(C21="",D21=""),"",IF(C21>=100,"—",ROUND((D21-C21)/(100-C21),2))) | G21: =A_kirish!AQ21 | H21: =B_yakuniy!AQ21 | I21: =IF(OR(G21="",H21=""),"",IF(MATCH(H21,Darajalar!$A$2:$A$5,0)<MATCH(G21,Darajalar!$A$2:$A$5,0),"↑",IF(MATCH(H21,Darajalar!$A$2:$A$5,0)=MATCH(G21,Darajalar!$A$2:$A$5,0),"=","↓"))) | J21: =IF(E21="","",IF(ABS(E21)<=7,"o‘zgarishsiz (±2 savol)",IF(E21>0,"o‘sdi","pasaydi"))) | K21: =A_kirish!AM21 | L21: =B_yakuniy!AM21 | M21: =A_kirish!AN21 | N21: =B_yakuniy!AN21 | O21: =Amaliy!J21 | P21: =Amaliy!R21 | Q21: =A_kirish!AT21 | U21: Sinf g — jami | V21: =IFERROR(ROUND((SUMPRODUCT(--(C6:C40<>""),--(D6:D40<>""),D6:D40)-SUMPRODUCT(--(C6:C40<>""),--(D6:D40<>""),C6:C40))/(SUMPRODUCT(--(C6:C40<>""),--(D6:D40<>""))*100-SUMPRODUCT(--(C6:C40<>""),--(D6:D40<>""),C6:C40)),2),"")
A22: 17 | B22: =IF(Royxat!B18="","",Royxat!B18) | C22: =A_kirish!AP22 | D22: =B_yakuniy!AP22 | E22: =IF(OR(C22="",D22=""),"",D22-C22) | F22: =IF(OR(C22="",D22=""),"",IF(C22>=100,"—",ROUND((D22-C22)/(100-C22),2))) | G22: =A_kirish!AQ22 | H22: =B_yakuniy!AQ22 | I22: =IF(OR(G22="",H22=""),"",IF(MATCH(H22,Darajalar!$A$2:$A$5,0)<MATCH(G22,Darajalar!$A$2:$A$5,0),"↑",IF(MATCH(H22,Darajalar!$A$2:$A$5,0)=MATCH(G22,Darajalar!$A$2:$A$5,0),"=","↓"))) | J22: =IF(E22="","",IF(ABS(E22)<=7,"o‘zgarishsiz (±2 savol)",IF(E22>0,"o‘sdi","pasaydi"))) | K22: =A_kirish!AM22 | L22: =B_yakuniy!AM22 | M22: =A_kirish!AN22 | N22: =B_yakuniy!AN22 | O22: =Amaliy!J22 | P22: =Amaliy!R22 | Q22: =A_kirish!AT22 | U22: Sinf g — tayanch (S1–S3) | V22: =IFERROR(ROUND((SUMPRODUCT(--(K6:K40<>""),--(L6:L40<>""),L6:L40)-SUMPRODUCT(--(K6:K40<>""),--(L6:L40<>""),K6:K40))/(SUMPRODUCT(--(K6:K40<>""),--(L6:L40<>""))*100-SUMPRODUCT(--(K6:K40<>""),--(L6:L40<>""),K6:K40)),2),"")
A23: 18 | B23: =IF(Royxat!B19="","",Royxat!B19) | C23: =A_kirish!AP23 | D23: =B_yakuniy!AP23 | E23: =IF(OR(C23="",D23=""),"",D23-C23) | F23: =IF(OR(C23="",D23=""),"",IF(C23>=100,"—",ROUND((D23-C23)/(100-C23),2))) | G23: =A_kirish!AQ23 | H23: =B_yakuniy!AQ23 | I23: =IF(OR(G23="",H23=""),"",IF(MATCH(H23,Darajalar!$A$2:$A$5,0)<MATCH(G23,Darajalar!$A$2:$A$5,0),"↑",IF(MATCH(H23,Darajalar!$A$2:$A$5,0)=MATCH(G23,Darajalar!$A$2:$A$5,0),"=","↓"))) | J23: =IF(E23="","",IF(ABS(E23)<=7,"o‘zgarishsiz (±2 savol)",IF(E23>0,"o‘sdi","pasaydi"))) | K23: =A_kirish!AM23 | L23: =B_yakuniy!AM23 | M23: =A_kirish!AN23 | N23: =B_yakuniy!AN23 | O23: =Amaliy!J23 | P23: =Amaliy!R23 | Q23: =A_kirish!AT23 | U23: Sinf g — 7-sinf (S4–S6) ★ asosiy | V23: =IFERROR(ROUND((SUMPRODUCT(--(M6:M40<>""),--(N6:N40<>""),N6:N40)-SUMPRODUCT(--(M6:M40<>""),--(N6:N40<>""),M6:M40))/(SUMPRODUCT(--(M6:M40<>""),--(N6:N40<>""))*100-SUMPRODUCT(--(M6:M40<>""),--(N6:N40<>""),M6:M40)),2),"")
A24: 19 | B24: =IF(Royxat!B20="","",Royxat!B20) | C24: =A_kirish!AP24 | D24: =B_yakuniy!AP24 | E24: =IF(OR(C24="",D24=""),"",D24-C24) | F24: =IF(OR(C24="",D24=""),"",IF(C24>=100,"—",ROUND((D24-C24)/(100-C24),2))) | G24: =A_kirish!AQ24 | H24: =B_yakuniy!AQ24 | I24: =IF(OR(G24="",H24=""),"",IF(MATCH(H24,Darajalar!$A$2:$A$5,0)<MATCH(G24,Darajalar!$A$2:$A$5,0),"↑",IF(MATCH(H24,Darajalar!$A$2:$A$5,0)=MATCH(G24,Darajalar!$A$2:$A$5,0),"=","↓"))) | J24: =IF(E24="","",IF(ABS(E24)<=7,"o‘zgarishsiz (±2 savol)",IF(E24>0,"o‘sdi","pasaydi"))) | K24: =A_kirish!AM24 | L24: =B_yakuniy!AM24 | M24: =A_kirish!AN24 | N24: =B_yakuniy!AN24 | O24: =Amaliy!J24 | P24: =Amaliy!R24 | Q24: =A_kirish!AT24 | U24: g talqini (jami) | V24: =IF(V21="","",IF(V21>=0.7,"Yuqori o‘sish",IF(V21>=0.3,"O‘rtacha o‘sish",IF(V21>=0,"Past o‘sish","Pasaygan"))))
A25: 20 | B25: =IF(Royxat!B21="","",Royxat!B21) | C25: =A_kirish!AP25 | D25: =B_yakuniy!AP25 | E25: =IF(OR(C25="",D25=""),"",D25-C25) | F25: =IF(OR(C25="",D25=""),"",IF(C25>=100,"—",ROUND((D25-C25)/(100-C25),2))) | G25: =A_kirish!AQ25 | H25: =B_yakuniy!AQ25 | I25: =IF(OR(G25="",H25=""),"",IF(MATCH(H25,Darajalar!$A$2:$A$5,0)<MATCH(G25,Darajalar!$A$2:$A$5,0),"↑",IF(MATCH(H25,Darajalar!$A$2:$A$5,0)=MATCH(G25,Darajalar!$A$2:$A$5,0),"=","↓"))) | J25: =IF(E25="","",IF(ABS(E25)<=7,"o‘zgarishsiz (±2 savol)",IF(E25>0,"o‘sdi","pasaydi"))) | K25: =A_kirish!AM25 | L25: =B_yakuniy!AM25 | M25: =A_kirish!AN25 | N25: =B_yakuniy!AN25 | O25: =Amaliy!J25 | P25: =Amaliy!R25 | Q25: =A_kirish!AT25 | U25: Daraja ko‘tarilgan | V25: =COUNTIF(I6:I40,"↑")
A26: 21 | B26: =IF(Royxat!B22="","",Royxat!B22) | C26: =A_kirish!AP26 | D26: =B_yakuniy!AP26 | E26: =IF(OR(C26="",D26=""),"",D26-C26) | F26: =IF(OR(C26="",D26=""),"",IF(C26>=100,"—",ROUND((D26-C26)/(100-C26),2))) | G26: =A_kirish!AQ26 | H26: =B_yakuniy!AQ26 | I26: =IF(OR(G26="",H26=""),"",IF(MATCH(H26,Darajalar!$A$2:$A$5,0)<MATCH(G26,Darajalar!$A$2:$A$5,0),"↑",IF(MATCH(H26,Darajalar!$A$2:$A$5,0)=MATCH(G26,Darajalar!$A$2:$A$5,0),"=","↓"))) | J26: =IF(E26="","",IF(ABS(E26)<=7,"o‘zgarishsiz (±2 savol)",IF(E26>0,"o‘sdi","pasaydi"))) | K26: =A_kirish!AM26 | L26: =B_yakuniy!AM26 | M26: =A_kirish!AN26 | N26: =B_yakuniy!AN26 | O26: =Amaliy!J26 | P26: =Amaliy!R26 | Q26: =A_kirish!AT26 | U26: Daraja o‘zgarmagan | V26: =COUNTIF(I6:I40,"=")
A27: 22 | B27: =IF(Royxat!B23="","",Royxat!B23) | C27: =A_kirish!AP27 | D27: =B_yakuniy!AP27 | E27: =IF(OR(C27="",D27=""),"",D27-C27) | F27: =IF(OR(C27="",D27=""),"",IF(C27>=100,"—",ROUND((D27-C27)/(100-C27),2))) | G27: =A_kirish!AQ27 | H27: =B_yakuniy!AQ27 | I27: =IF(OR(G27="",H27=""),"",IF(MATCH(H27,Darajalar!$A$2:$A$5,0)<MATCH(G27,Darajalar!$A$2:$A$5,0),"↑",IF(MATCH(H27,Darajalar!$A$2:$A$5,0)=MATCH(G27,Darajalar!$A$2:$A$5,0),"=","↓"))) | J27: =IF(E27="","",IF(ABS(E27)<=7,"o‘zgarishsiz (±2 savol)",IF(E27>0,"o‘sdi","pasaydi"))) | K27: =A_kirish!AM27 | L27: =B_yakuniy!AM27 | M27: =A_kirish!AN27 | N27: =B_yakuniy!AN27 | O27: =Amaliy!J27 | P27: =Amaliy!R27 | Q27: =A_kirish!AT27 | U27: Daraja tushgan | V27: =COUNTIF(I6:I40,"↓")
